Workbook

Sheet Данные
A1: тип_респондента | B1: пол | C1: семейное_положение | D1: дети | E1: частота_покупки | F1: цена_слишком_низкая | G1: цена_выгодная_сделка | H1: цена_завышенная_но_куплю | I1: цена_слишком_высокая | J1: проживание | K1: доля_обязательных_платежей
A2: Людмила Петровна | B2: женский | C2: состоит в браке | D2: дети есть, но они уже большие (старше 18) | E2: одну пару раз в два года или реже | F2: 600 | G2: 800 | H2: 2400 | I2: 3500 | J2: город с населением до 500 тыс. человек | K2: от 50% до 75%
A3: Илья | B3: мужской | C3: в гражданском браке | D3: нет детей | E3: две-три пары в год | F3: 1500 | G3: 3800 | H3: 8700 | I3: 16500 | J3: город-миллионник | K3: менее 25%
A4: Михаил | B4: мужской | C4: состоит в браке | D4: один ребенок | E4: обычно одну пару в год | F4: 2000 | G4: 4000 | H4: 9900 | I4: 20000 | J4: город-миллионник | K4: от 25% до 50%
A5: Руслан | B5: мужской | C5: состоит в браке | D5: один ребенок | E5: две-три пары в год | F5: 800 | G5: 1800 | H5: 2700 | I5: 4500 | J5: город с населением до 500 тыс. человек | K5: от 50% до 75%
A6: Алексей | B6: мужской | C6: состоит в браке | D6: нет детей | E6: обычно одну пару в год | F6: 1800 | G6: 3800 | H6: 8400 | I6: 14500 | J6: большой город с населением несколько миллионов | K6: менее 25%
A7: Алексей | B7: мужской | C7: состоит в браке | D7: один ребенок | E7: обычно одну пару в год | F7: 1400 | G7: 4600 | H7: 7500 | I7: 13500 | J7: большой город с населением несколько миллионов | K7: менее 25%
A8: Екатерина | B8: женский | C8: состоит в браке | D8: есть двое и более | E8: обычно одну пару в год | F8: 700 | G8: 2400 | H8: 4200 | I8: 6000 | J8: город с населением до 500 тыс. человек | K8: от 50% до 75%
A9: Илья | B9: мужской | C9: в гражданском браке | D9: нет детей | E9: две-три пары в год | F9: 2000 | G9: 3600 | H9: 8400 | I9: 13000 | J9: город-миллионник | K9: менее 25%
A10: Руслан | B10: мужской | C10: состоит в браке | D10: есть двое и более | E10: две-три пары в год | F10: 800 | G10: 1800 | H10: 2700 | I10: 4000 | J10: город с населением до 500 тыс. человек | K10: от 25% до 50%
A11: Михаил | B11: мужской | C11: состоит в браке | D11: есть двое и более | E11: обычно одну пару в год | F11: 1900 | G11: 4400 | H11: 9600 | I11: 18000 | J11: город-миллионник | K11: от 25% до 50%
A12: Екатерина | B12: женский | C12: состоит в браке | D12: есть двое и более | E12: обычно одну пару в год | F12: 800 | G12: 2200 | H12: 4800 | I12: 7500 | J12: город-миллионник | K12: от 50% до 75%
A13: Алиса | B13: женский | C13: в гражданском браке | D13: нет детей | E13: обычно одну пару в год | F13: 2000 | G13: 6000 | H13: 14100 | I13: 24500 | J13: большой город с населением несколько миллионов | K13: менее 25%
... A1001: Кристина | B1001: женский | C1001: в гражданском браке | D1001: нет детей | E1001: две-три пары в год | F1001: 1300 | G1001: 3000 | H1001: 8700 | I1001: 12000 | J1001: город-миллионник | K1001: от 25% до 50%

Sheet результат
Q1: A | R1: B | S1: C | T1: D | U1: E | V1: J | W1: K
Q2: тип респондента | R2: пол | S2: семейное положение | T2: дети | U2: частота покупки | V2: проживание | W2: доля обязательных платежей
Q3: Q4:Q13 | R3: R4:R5 | S3: S4:S6 | T3: T4:T7 | U3: U4:U6 | V3: V4:V7 | W3: W4:W7
Q4: Людмила Петровна | R4: женский | S4: состоит в браке | T4: дети есть, но они уже большие (старше 18) | U4: одну пару раз в два года или реже | V4: город с населением до 500 тыс. человек | W4: от 50% до 75%
Q5: Илья | R5: мужской | S5: в гражданском браке | T5: нет детей | U5: две-три пары в год | V5: город-миллионник | W5: менее 25%
Q6: Михаил | S6: не в отношениях | T6: один ребенок | U6: обычно одну пару в год | V6: большой город с населением несколько миллионов | W6: от 25% до 50%
Q7: Руслан | T7: есть двое и более | V7: небольшой поселок / город с населением менее 100 тыс. человек
Q8: Алексей
Q9: Екатерина
Q10: Алиса
Q11: Данил
Q12: Кристина
Q13: Арина
B15: 1 Группа
B16: Тип группы | C16: Значение | D16: Выборка | F16: столб. | G16: строка | Q16: =COUNTIF(INDIRECT("Данные!"&Q$1&":"&Q$1),[1]результат!Q4) -> 56 | R16: =COUNTIF(INDIRECT("Данные!"&R$1&":"&R$1),[1]результат!R4) -> 364 | S16: =COUNTIF(INDIRECT("Данные!"&S$1&":"&S$1),[1]результат!S4) -> 577 | T16: =COUNTIF(INDIRECT("Данные!"&T$1&":"&T$1),[1]результат!T4) -> 56 | U16: =COUNTIF(INDIRECT("Данные!"&U$1&":"&U$1),[1]результат!U4) -> 56 | V16: =COUNTIF(INDIRECT("Данные!"&V$1&":"&V$1),[1]результат!V4) -> 230 | W16: =COUNTIF(INDIRECT("Данные!"&W$1&":"&W$1),[1]результат!W4) -> 114
A17: Выберите свою группу и значение >> | B17: дети | C17: один ребенок | D17: =INDEX($Q$16:$W$25,G17,F17)&" респондентов" -> 223 респондентов | F17: =MATCH(B17,$Q$2:$W$2,0) -> 4 | G17: =MATCH(C17,INDIRECT(HLOOKUP(B17,$Q$2:$W$3,2,0)),0) -> 3 | Q17: =COUNTIF(INDIRECT("Данные!"&Q$1&":"&Q$1),[1]результат!Q5) -> 161 | R17: =COUNTIF(INDIRECT("Данные!"&R$1&":"&R$1),[1]результат!R5) -> 636 | S17: =COUNTIF(INDIRECT("Данные!"&S$1&":"&S$1),[1]результат!S5) -> 184 | T17: =COUNTIF(INDIRECT("Данные!"&T$1&":"&T$1),[1]результат!T5) -> 493 | U17: =COUNTIF(INDIRECT("Данные!"&U$1&":"&U$1),[1]результат!U5) -> 435 | V17: =COUNTIF(INDIRECT("Данные!"&V$1&":"&V$1),[1]результат!V5) -> 550 | W17: =COUNTIF(INDIRECT("Данные!"&W$1&":"&W$1),[1]результат!W5) -> 495
A18: (из списка) | Q18: =COUNTIF(INDIRECT("Данные!"&Q$1&":"&Q$1),[1]результат!Q6) -> 106 | S18: =COUNTIF(INDIRECT("Данные!"&S$1&":"&S$1),[1]результат!S6) -> 239 | T18: =COUNTIF(INDIRECT("Данные!"&T$1&":"&T$1),[1]результат!T6) -> 223 | U18: =COUNTIF(INDIRECT("Данные!"&U$1&":"&U$1),[1]результат!U6) -> 509 | V18: =COUNTIF(INDIRECT("Данные!"&V$1&":"&V$1),[1]результат!V6) -> 190 | W18: =COUNTIF(INDIRECT("Данные!"&W$1&":"&W$1),[1]результат!W6) -> 391
B19: PMC | C19: PME | F19: График | Q19: =COUNTIF(INDIRECT("Данные!"&Q$1&":"&Q$1),[1]результат!Q7) -> 121 | T19: =COUNTIF(INDIRECT("Данные!"&T$1&":"&T$1),[1]результат!T7) -> 228 | V19: =COUNTIF(INDIRECT("Данные!"&V$1&":"&V$1),[1]результат!V7) -> 30
A20: Допустимый ценовой диапазон | B20: 2400 | C20: 4880 | Q20: =COUNTIF(INDIRECT("Данные!"&Q$1&":"&Q$1),[1]результат!Q8) -> 152
Q21: =COUNTIF(INDIRECT("Данные!"&Q$1&":"&Q$1),[1]результат!Q9) -> 117
A22: Точка безразличия IPP | B22: 4478 | Q22: =COUNTIF(INDIRECT("Данные!"&Q$1&":"&Q$1),[1]результат!Q10) -> 38
Q23: =COUNTIF(INDIRECT("Данные!"&Q$1&":"&Q$1),[1]результат!Q11) -> 96
Q24: =COUNTIF(INDIRECT("Данные!"&Q$1&":"&Q$1),[1]результат!Q12) -> 104
Q25: =COUNTIF(INDIRECT("Данные!"&Q$1&":"&Q$1),[1]результат!Q13) -> 49
B39: 2 Группа
B40: Тип группы | C40: Значение | D40: Выборка | F40: столб. | G40: строка
A41: Выберите свою группу и значение >> | B41: дети | C41: нет детей | D41: =INDEX($Q$16:$W$25,G41,F41)&" респондентов" -> 493 респондентов | F41: =MATCH(B41,$Q$2:$W$2,0) -> 4 | G41: =MATCH(C41,INDIRECT(HLOOKUP(B41,$Q$2:$W$3,2,0)),0) -> 2
A42: (из списка)
B43: PMC | C43: PME | F43: График
A44: Допустимый ценовой диапазон | B44: 2920 | C44: 5950
A46: Точка безразличия IPP | B46: 4850
B63: 3 Группа
B64: Тип группы | C64: Значение | D64: Выборка | F64: столб. | G64: строка
A65: Выберите свою группу и значение >> | B65: пол | C65: женский | D65: =INDEX($Q$16:$W$25,G65,F65)&" респондентов" -> 364 респондентов | F65: =MATCH(B65,$Q$2:$W$2,0) -> 2 | G65: =MATCH(C65,INDIRECT(HLOOKUP(B65,$Q$2:$W$3,2,0)),0) -> 1
A66: (из списка)
B67: PMC | C67: PME | F67: График
A68: Допустимый ценовой диапазон | B68: 2370 | C68: 4470
A70: Точка безразличия IPP | B70: 3485
B88: 4 Группа
B89: Тип группы | C89: Значение | D89: Выборка | F89: столб. | G89: строка
...

Sheet 1 способ
A1: сл. низкая | E1: выг. сделка | I1: завышенная, куплю | M1: сл. высокая | O1: сл. Дешево | P1: респ. | Q1: накоп. | R1: доля | S1: дешево | T1: респ. | U1: накоп. | V1: доля | W1: дорого | X1: респ. | Y1: накоп. | Z1: доля | AA1: сл. Дорого | AB1: респ. | AC1: накоп. | AD1: доля
A2: 2000 | E2: 4000 | I2: 9900 | M2: 20000 | O2: 2400 | P2: =COUNTIF(A:A,O2) -> 5 | Q2: =SUM(P$2:P2) -> 5 | R2: =Q2/MAX(Q:Q) -> 0.022421525 | S2: 5800 | T2: =COUNTIF(E:E,S2) -> 4 | U2: =SUM(T$2:T2) -> 4 | V2: =U2/MAX(U:U) -> 0.01793722 | W2: 2400 | X2: =COUNTIF(I:I,W2) -> 4 | Y2: =SUM(X$2:X2) -> 4 | Z2: =Y2/MAX(Y:Y) -> 0.01793722 | AA2: 4000 | AB2: =COUNTIF(M:M,AA2) -> 12 | AC2: =SUM(AB$2:AB2) -> 12 | AD2: =AC2/MAX(AC:AC) -> 0.053811659
A3: 800 | E3: 1800 | I3: 2700 | M3: 4500 | O3: 2300 | P3: =COUNTIF(A:A,O3) -> 8 | Q3: =SUM(P$2:P3) -> 13 | R3: =Q3/MAX(Q:Q) -> 0.058295964 | S3: 5600 | T3: =COUNTIF(E:E,S3) -> 6 | U3: =SUM(T$2:T3) -> 10 | V3: =U3/MAX(U:U) -> 0.044843049 | W3: 2700 | X3: =COUNTIF(I:I,W3) -> 24 | Y3: =SUM(X$2:X3) -> 28 | Z3: =Y3/MAX(Y:Y) -> 0.12556054 | AA3: 4500 | AB3: =COUNTIF(M:M,AA3) -> 22 | AC3: =SUM(AB$2:AB3) -> 34 | AD3: =AC3/MAX(AC:AC) -> 0.15246637
A4: 1400 | E4: 4600 | I4: 7500 | M4: 13500 | O4: 2200 | P4: =COUNTIF(A:A,O4) -> 1 | Q4: =SUM(P$2:P4) -> 14 | R4: =Q4/MAX(Q:Q) -> 0.062780269 | S4: 5400 | T4: =COUNTIF(E:E,S4) -> 5 | U4: =SUM(T$2:T4) -> 15 | V4: =U4/MAX(U:U) -> 0.067264574 | W4: 3000 | X4: =COUNTIF(I:I,W4) -> 19 | Y4: =SUM(X$2:X4) -> 47 | Z4: =Y4/MAX(Y:Y) -> 0.21076233 | AA4: 5000 | AB4: =COUNTIF(M:M,AA4) -> 16 | AC4: =SUM(AB$2:AB4) -> 50 | AD4: =AC4/MAX(AC:AC) -> 0.22421525
A5: 1300 | E5: 3400 | I5: 9600 | M5: 14000 | O5: 2100 | P5: =COUNTIF(A:A,O5) -> 3 | Q5: =SUM(P$2:P5) -> 17 | R5: =Q5/MAX(Q:Q) -> 0.076233184 | S5: 5200 | T5: =COUNTIF(E:E,S5) -> 8 | U5: =SUM(T$2:T5) -> 23 | V5: =U5/MAX(U:U) -> 0.10313901 | W5: 3300 | X5: =COUNTIF(I:I,W5) -> 21 | Y5: =SUM(X$2:X5) -> 68 | Z5: =Y5/MAX(Y:Y) -> 0.30493274 | AA5: 5500 | AB5: =COUNTIF(M:M,AA5) -> 10 | AC5: =SUM(AB$2:AB5) -> 60 | AD5: =AC5/MAX(AC:AC) -> 0.2690583
A6: 1100 | E6: 5000 | I6: 7200 | M6: 12500 | O6: 2000 | P6: =COUNTIF(A:A,O6) -> 13 | Q6: =SUM(P$2:P6) -> 30 | R6: =Q6/MAX(Q:Q) -> 0.13452915 | S6: 5000 | T6: =COUNTIF(E:E,S6) -> 16 | U6: =SUM(T$2:T6) -> 39 | V6: =U6/MAX(U:U) -> 0.17488789 | W6: 3600 | X6: =COUNTIF(I:I,W6) -> 1 | Y6: =SUM(X$2:X6) -> 69 | Z6: =Y6/MAX(Y:Y) -> 0.30941704 | AA6: 6000 | AB6: =COUNTIF(M:M,AA6) -> 9 | AC6: =SUM(AB$2:AB6) -> 69 | AD6: =AC6/MAX(AC:AC) -> 0.30941704
A7: 1800 | E7: 5000 | I7: 8100 | M7: 14000 | O7: 1900 | P7: =COUNTIF(A:A,O7) -> 10 | Q7: =SUM(P$2:P7) -> 40 | R7: =Q7/MAX(Q:Q) -> 0.1793722 | S7: 4800 | T7: =COUNTIF(E:E,S7) -> 11 | U7: =SUM(T$2:T7) -> 50 | V7: =U7/MAX(U:U) -> 0.22421525 | W7: 7200 | X7: =COUNTIF(I:I,W7) -> 11 | Y7: =SUM(X$2:X7) -> 80 | Z7: =Y7/MAX(Y:Y) -> 0.35874439 | AA7: 12000 | AB7: =COUNTIF(M:M,AA7) -> 12 | AC7: =SUM(AB$2:AB7) -> 81 | AD7: =AC7/MAX(AC:AC) -> 0.3632287
A8: 700 | E8: 1200 | I8: 2700 | M8: 5500 | O8: 1800 | P8: =COUNTIF(A:A,O8) -> 17 | Q8: =SUM(P$2:P8) -> 57 | R8: =Q8/MAX(Q:Q) -> 0.25560538 | S8: 4600 | T8: =COUNTIF(E:E,S8) -> 15 | U8: =SUM(T$2:T8) -> 65 | V8: =U8/MAX(U:U) -> 0.29147982 | W8: 7500 | X8: =COUNTIF(I:I,W8) -> 7 | Y8: =SUM(X$2:X8) -> 87 | Z8: =Y8/MAX(Y:Y) -> 0.39013453 | AA8: 12500 | AB8: =COUNTIF(M:M,AA8) -> 22 | AC8: =SUM(AB$2:AB8) -> 103 | AD8: =AC8/MAX(AC:AC) -> 0.46188341
A9: 400 | E9: 1800 | I9: 3300 | M9: 5500 | O9: 1700 | P9: =COUNTIF(A:A,O9) -> 16 | Q9: =SUM(P$2:P9) -> 73 | R9: =Q9/MAX(Q:Q) -> 0.32735426 | S9: 4400 | T9: =COUNTIF(E:E,S9) -> 11 | U9: =SUM(T$2:T9) -> 76 | V9: =U9/MAX(U:U) -> 0.34080717 | W9: 7800 | X9: =COUNTIF(I:I,W9) -> 12 | Y9: =SUM(X$2:X9) -> 99 | Z9: =Y9/MAX(Y:Y) -> 0.44394619 | AA9: 13000 | AB9: =COUNTIF(M:M,AA9) -> 14 | AC9: =SUM(AB$2:AB9) -> 117 | AD9: =AC9/MAX(AC:AC) -> 0.52466368
A10: 400 | E10: 1000 | I10: 3300 | M10: 6000 | O10: 1600 | P10: =COUNTIF(A:A,O10) -> 19 | Q10: =SUM(P$2:P10) -> 92 | R10: =Q10/MAX(Q:Q) -> 0.41255605 | S10: 4200 | T10: =COUNTIF(E:E,S10) -> 17 | U10: =SUM(T$2:T10) -> 93 | V10: =U10/MAX(U:U) -> 0.41704036 | W10: 8100 | X10: =COUNTIF(I:I,W10) -> 14 | Y10: =SUM(X$2:X10) -> 113 | Z10: =Y10/MAX(Y:Y) -> 0.50672646 | AA10: 13500 | AB10: =COUNTIF(M:M,AA10) -> 15 | AC10: =SUM(AB$2:AB10) -> 132 | AD10: =AC10/MAX(AC:AC) -> 0.59192825
A11: 1000 | E11: 3200 | I11: 7500 | M11: 13000 | O11: 1500 | P11: =COUNTIF(A:A,O11) -> 5 | Q11: =SUM(P$2:P11) -> 97 | R11: =Q11/MAX(Q:Q) -> 0.43497758 | S11: 4000 | T11: =COUNTIF(E:E,S11) -> 14 | U11: =SUM(T$2:T11) -> 107 | V11: =U11/MAX(U:U) -> 0.47982063 | W11: 8400 | X11: =COUNTIF(I:I,W11) -> 14 | Y11: =SUM(X$2:X11) -> 127 | Z11: =Y11/MAX(Y:Y) -> 0.56950673 | AA11: 14000 | AB11: =COUNTIF(M:M,AA11) -> 19 | AC11: =SUM(AB$2:AB11) -> 151 | AD11: =AC11/MAX(AC:AC) -> 0.67713004
A12: 2000 | E12: 5200 | I12: 9600 | M12: 16000 | O12: 1400 | P12: =COUNTIF(A:A,O12) -> 11 | Q12: =SUM(P$2:P12) -> 108 | R12: =Q12/MAX(Q:Q) -> 0.48430493 | S12: 3800 | T12: =COUNTIF(E:E,S12) -> 10 | U12: =SUM(T$2:T12) -> 117 | V12: =U12/MAX(U:U) -> 0.52466368 | W12: 8700 | X12: =COUNTIF(I:I,W12) -> 10 | Y12: =SUM(X$2:X12) -> 137 | Z12: =Y12/MAX(Y:Y) -> 0.61434978 | AA12: 14500 | AB12: =COUNTIF(M:M,AA12) -> 16 | AC12: =SUM(AB$2:AB12) -> 167 | AD12: =AC12/MAX(AC:AC) -> 0.74887892
A13: 1800 | E13: 4200 | I13: 7800 | M13: 14500 | O13: 1300 | P13: =COUNTIF(A:A,O13) -> 9 | Q13: =SUM(P$2:P13) -> 117 | R13: =Q13/MAX(Q:Q) -> 0.52466368 | S13: 3600 | T13: =COUNTIF(E:E,S13) -> 15 | U13: =SUM(T$2:T13) -> 132 | V13: =U13/MAX(U:U) -> 0.59192825 | W13: 9000 | X13: =COUNTIF(I:I,W13) -> 12 | Y13: =SUM(X$2:X13) -> 149 | Z13: =Y13/MAX(Y:Y) -> 0.66816143 | AA13: 15000 | AB13: =COUNTIF(M:M,AA13) -> 10 | AC13: =SUM(AB$2:AB13) -> 177 | AD13: =AC13/MAX(AC:AC) -> 0.79372197
... A21: 2300 | E21: 5600 | I21: 11100 | M21: 19500 | O21: 400 | P21: =COUNTIF(A:A,O21) -> 8 | Q21: =SUM(P$2:P21) -> 223 | R21: =Q21/MAX(Q:Q) -> 1 | S21: 1000 | T21: =COUNTIF(E:E,S21) -> 10 | U21: =SUM(T$2:T21) -> 223 | V21: =U21/MAX(U:U) -> 1 | W21: 11400 | X21: =COUNTIF(I:I,W21) -> 9 | Y21: =SUM(X$2:X21) -> 218 | Z21: =Y21/MAX(Y:Y) -> 0.97757848 | AA21: 19000 | AB21: =COUNTIF(M:M,AA21) -> 1 | AC21: =SUM(AB$2:AB21) -> 214 | AD21: =AC21/MAX(AC:AC) -> 0.95964126
A22: 1800 | E22: 4200 | I22: 9900 | M22: 14000 | W22: 11700 | X22: =COUNTIF(I:I,W22) -> 4 | Y22: =SUM(X$2:X22) -> 222 | Z22: =Y22/MAX(Y:Y) -> 0.9955157 | AA22: 19500 | AB22: =COUNTIF(M:M,AA22) -> 6 | AC22: =SUM(AB$2:AB22) -> 220 | AD22: =AC22/MAX(AC:AC) -> 0.98654709
A23: 800 | E23: 1000 | I23: 3300 | M23: 4500 | W23: 12000 | X23: =COUNTIF(I:I,W23) -> 1 | Y23: =SUM(X$2:X23) -> 223 | Z23: =Y23/MAX(Y:Y) -> 1 | AA23: 20000 | AB23: =COUNTIF(M:M,AA23) -> 3 | AC23: =SUM(AB$2:AB23) -> 223 | AD23: =AC23/MAX(AC:AC) -> 1
A24: 1200 | E24: 4200 | I24: 9600 | M24: 14500
A25: 1900 | E25: 5000 | I25: 11100 | M25: 16500 | S25: X | T25: Y
A26: 400 | E26: 1400 | I26: 2700 | M26: 5000 | R26: A | S26: 4600 | T26: 0.29147982
A27: 500 | E27: 1000 | I27: 2700 | M27: 5000 | R27: B | S27: 4400 | T27: 0.34080717
A28: 1700 | E28: 3000 | I28: 8100 | M28: 12500 | R28: k | S28: =(T27-T26)/(S27-S26) -> -0.00024663677
A29: 1900 | E29: 4600 | I29: 9900 | M29: 19500 | R29: b | S29: =T26-S28*S26 -> 1.426009
A30: 1000 | E30: 5000 | I30: 9600 | M30: 14500
A31: 1900 | E31: 4400 | I31: 8700 | M31: 12000
A32: 500 | E32: 1600 | I32: 3000 | M32: 4500 | S32: X | T32: Y
A33: 1200 | E33: 5000 | I33: 9600 | M33: 13000 | R33: C | S33: 3600 | T33: 0.30941704
A34: 1100 | E34: 3600 | I34: 9300 | M34: 13000 | R34: D | S34: 7200 | T34: 0.35874439
A35: 1900 | E35: 4000 | I35: 7800 | M35: 13500 | R35: K2 | S35: =(T34-T33)/(S34-S33) -> 1.3702043e-05
A36: 1200 | E36: 4400 | I36: 7200 | M36: 14500 | R36: B2 | S36: =T33-S35*S33 -> 0.26008969
A37: 500 | E37: 1600 | I37: 2700 | M37: 6000
A38: 1600 | E38: 4600 | I38: 9900 | M38: 14000
A39: 1200 | E39: 3400 | I39: 8700 | M39: 14500 | R39: IPP | S39: =(S36-S29)/(S28-S35) -> 4478.4689
A40: 1700 | E40: 4400 | I40: 11400 | M40: 19500
A41: 2000 | E41: 5800 | I41: 9600 | M41: 19500
A42: 1200 | E42: 4800 | I42: 9000 | M42: 12500
A43: 800 | E43: 1600 | I43: 2700 | M43: 4000
A44: 1700 | E44: 4800 | I44: 8400 | M44: 13000
A45: 1900 | E45: 4400 | I45: 9300 | M45: 13500
A46: 1700 | E46: 4600 | I46: 9000 | M46: 12500
A47: 1800 | E47: 4800 | I47: 7800 | M47: 14500
...

Sheet 2 способ
A1: сл. Дешево | B1: дешево | C1: дорого | D1: сл. Дорого | F1: мин | G1: =MIN(A:D) -> 300 | I1: Цена | J1: сл. Дешево | K1: дешево | L1: дорого | M1: сл. Дорого
A2: 1500 | B2: 3800 | C2: 8700 | D2: 16500 | F2: макс | G2: =MAX(A:D) -> 24500 | I2: 300 | J2: =COUNTIF(A:A,">="&$I2)/$G$7 -> 1 | K2: =COUNTIF(B:B,">="&$I2)/$G$7 -> 1 | L2: =COUNTIF(C:C,"<="&$I2)/$G$7 -> 0 | M2: =COUNTIF(D:D,"<="&$I2)/$G$7 -> 0
A3: 1800 | B3: 3800 | C3: 8400 | D3: 14500 | F3: сред | G3: =AVERAGE(A:D) -> 6343.7627 | I3: 400 | J3: =COUNTIF(A:A,">="&$I3)/$G$7 -> 0.99188641 | K3: =COUNTIF(B:B,">="&$I3)/$G$7 -> 1 | L3: =COUNTIF(C:C,"<="&$I3)/$G$7 -> 0 | M3: =COUNTIF(D:D,"<="&$I3)/$G$7 -> 0
A4: 2000 | B4: 3600 | C4: 8400 | D4: 13000 | F4: медиана | G4: =MEDIAN(A:D) -> 4800 | I4: 500 | J4: =COUNTIF(A:A,">="&$I4)/$G$7 -> 0.95740365 | K4: =COUNTIF(B:B,">="&$I4)/$G$7 -> 1 | L4: =COUNTIF(C:C,"<="&$I4)/$G$7 -> 0 | M4: =COUNTIF(D:D,"<="&$I4)/$G$7 -> 0
A5: 2000 | B5: 6000 | C5: 14100 | D5: 24500 | I5: 600 | J5: =COUNTIF(A:A,">="&$I5)/$G$7 -> 0.92900609 | K5: =COUNTIF(B:B,">="&$I5)/$G$7 -> 1 | L5: =COUNTIF(C:C,"<="&$I5)/$G$7 -> 0 | M5: =COUNTIF(D:D,"<="&$I5)/$G$7 -> 0
A6: 1300 | B6: 5000 | C6: 9900 | D6: 14500 | I6: 700 | J6: =COUNTIF(A:A,">="&$I6)/$G$7 -> 0.86004057 | K6: =COUNTIF(B:B,">="&$I6)/$G$7 -> 1 | L6: =COUNTIF(C:C,"<="&$I6)/$G$7 -> 0 | M6: =COUNTIF(D:D,"<="&$I6)/$G$7 -> 0
A7: 900 | B7: 1800 | C7: 4800 | D7: 8000 | F7: респонденты | G7: =COUNT(A:A) -> 493 | I7: 800 | J7: =COUNTIF(A:A,">="&$I7)/$G$7 -> 0.81135903 | K7: =COUNTIF(B:B,">="&$I7)/$G$7 -> 1 | L7: =COUNTIF(C:C,"<="&$I7)/$G$7 -> 0 | M7: =COUNTIF(D:D,"<="&$I7)/$G$7 -> 0
A8: 1400 | B8: 3800 | C8: 6900 | D8: 11500 | I8: 900 | J8: =COUNTIF(A:A,">="&$I8)/$G$7 -> 0.76673428 | K8: =COUNTIF(B:B,">="&$I8)/$G$7 -> 1 | L8: =COUNTIF(C:C,"<="&$I8)/$G$7 -> 0 | M8: =COUNTIF(D:D,"<="&$I8)/$G$7 -> 0
A9: 700 | B9: 2400 | C9: 4800 | D9: 9500 | I9: 1000 | J9: =COUNTIF(A:A,">="&$I9)/$G$7 -> 0.67545639 | K9: =COUNTIF(B:B,">="&$I9)/$G$7 -> 1 | L9: =COUNTIF(C:C,"<="&$I9)/$G$7 -> 0 | M9: =COUNTIF(D:D,"<="&$I9)/$G$7 -> 0
A10: 1500 | B10: 3400 | C10: 9600 | D10: 13000 | I10: 1100 | J10: =COUNTIF(A:A,">="&$I10)/$G$7 -> 0.59026369 | K10: =COUNTIF(B:B,">="&$I10)/$G$7 -> 0.99188641 | L10: =COUNTIF(C:C,"<="&$I10)/$G$7 -> 0 | M10: =COUNTIF(D:D,"<="&$I10)/$G$7 -> 0
A11: 700 | B11: 2200 | C11: 4800 | D11: 8000 | I11: 1200 | J11: =COUNTIF(A:A,">="&$I11)/$G$7 -> 0.53752535 | K11: =COUNTIF(B:B,">="&$I11)/$G$7 -> 0.99188641 | L11: =COUNTIF(C:C,"<="&$I11)/$G$7 -> 0 | M11: =COUNTIF(D:D,"<="&$I11)/$G$7 -> 0
A12: 1400 | B12: 3800 | C12: 6900 | D12: 13000 | I12: 1300 | J12: =COUNTIF(A:A,">="&$I12)/$G$7 -> 0.47667343 | K12: =COUNTIF(B:B,">="&$I12)/$G$7 -> 0.97160243 | L12: =COUNTIF(C:C,"<="&$I12)/$G$7 -> 0 | M12: =COUNTIF(D:D,"<="&$I12)/$G$7 -> 0
A13: 1200 | B13: 5000 | C13: 8100 | D13: 13500 | I13: 1400 | J13: =COUNTIF(A:A,">="&$I13)/$G$7 -> 0.40567951 | K13: =COUNTIF(B:B,">="&$I13)/$G$7 -> 0.97160243 | L13: =COUNTIF(C:C,"<="&$I13)/$G$7 -> 0 | M13: =COUNTIF(D:D,"<="&$I13)/$G$7 -> 0
A14: 1400 | B14: 3600 | C14: 7200 | D14: 12500 | I14: 1500 | J14: =COUNTIF(A:A,">="&$I14)/$G$7 -> 0.32251521 | K14: =COUNTIF(B:B,">="&$I14)/$G$7 -> 0.95131846 | L14: =COUNTIF(C:C,"<="&$I14)/$G$7 -> 0 | M14: =COUNTIF(D:D,"<="&$I14)/$G$7 -> 0
A15: 1100 | B15: 3800 | C15: 8700 | D15: 15000 | I15: 1600 | J15: =COUNTIF(A:A,">="&$I15)/$G$7 -> 0.2494929 | K15: =COUNTIF(B:B,">="&$I15)/$G$7 -> 0.95131846 | L15: =COUNTIF(C:C,"<="&$I15)/$G$7 -> 0 | M15: =COUNTIF(D:D,"<="&$I15)/$G$7 -> 0
A16: 2500 | B16: 6600 | C16: 13200 | D16: 22000 | I16: 1700 | J16: =COUNTIF(A:A,">="&$I16)/$G$7 -> 0.20283976 | K16: =COUNTIF(B:B,">="&$I16)/$G$7 -> 0.88640974 | L16: =COUNTIF(C:C,"<="&$I16)/$G$7 -> 0 | M16: =COUNTIF(D:D,"<="&$I16)/$G$7 -> 0
A17: 1400 | B17: 4400 | C17: 10500 | D17: 18000 | I17: 1800 | J17: =COUNTIF(A:A,">="&$I17)/$G$7 -> 0.1643002 | K17: =COUNTIF(B:B,">="&$I17)/$G$7 -> 0.88640974 | L17: =COUNTIF(C:C,"<="&$I17)/$G$7 -> 0 | M17: =COUNTIF(D:D,"<="&$I17)/$G$7 -> 0
A18: 1000 | B18: 2000 | C18: 5400 | D18: 8000 | I18: 1900 | J18: =COUNTIF(A:A,">="&$I18)/$G$7 -> 0.13184584 | K18: =COUNTIF(B:B,">="&$I18)/$G$7 -> 0.831643 | L18: =COUNTIF(C:C,"<="&$I18)/$G$7 -> 0 | M18: =COUNTIF(D:D,"<="&$I18)/$G$7 -> 0
A19: 800 | B19: 3000 | C19: 8400 | D19: 12500 | I19: 2000 | J19: =COUNTIF(A:A,">="&$I19)/$G$7 -> 0.089249493 | K19: =COUNTIF(B:B,">="&$I19)/$G$7 -> 0.831643 | L19: =COUNTIF(C:C,"<="&$I19)/$G$7 -> 0 | M19: =COUNTIF(D:D,"<="&$I19)/$G$7 -> 0
... A99: 1600 | B99: 3600 | C99: 9900 | D99: 14500 | I99: 10000 | J99: =COUNTIF(A:A,">="&$I99)/$G$7 -> 0 | K99: =COUNTIF(B:B,">="&$I99)/$G$7 -> 0 | L99: =COUNTIF(C:C,"<="&$I99)/$G$7 -> 0.8296146 | M99: =COUNTIF(D:D,"<="&$I99)/$G$7 -> 0.30831643
A100: 1800 | B100: 4800 | C100: 9000 | D100: 13500
A101: 1000 | B101: 5400 | C101: 10500 | D101: 14000
A102: 600 | B102: 2000 | C102: 3900 | D102: 5500
A103: 700 | B103: 1600 | C103: 4800 | D103: 9500
A104: 500 | B104: 2000 | C104: 5700 | D104: 7500
A105: 1200 | B105: 3600 | C105: 11100 | D105: 17000
A106: 1700 | B106: 4600 | C106: 9000 | D106: 13500
A107: 400 | B107: 1200 | C107: 3600 | D107: 6000
A108: 1200 | B108: 4200 | C108: 7800 | D108: 14000
A109: 1600 | B109: 3600 | C109: 10200 | D109: 13000
A110: 600 | B110: 1800 | C110: 3000 | D110: 6000
A111: 700 | B111: 1800 | C111: 4500 | D111: 6000
... A494: 1300 | B494: 3000 | C494: 8700 | D494: 12000

Sheet 3 способ
A1: сл. Дешево | B1: дешево | C1: дорого | D1: сл. Дорого | F1: мин | G1: =MIN(A:D) -> 300 | I1: Цена | J1: сл. Дешево | K1: дешево | L1: дорого | M1: сл. Дорого
A2: 600 | B2: 800 | C2: 2400 | D2: 3500 | F2: макс | G2: =MAX(A:D) -> 24500 | I2: 300 | J2: =COUNTIF(A:A,">="&$I2)/$G$7 -> 1 | K2: =COUNTIF(B:B,">="&$I2)/$G$7 -> 1 | L2: =COUNTIF(C:C,"<="&$I2)/$G$7 -> 0 | M2: =COUNTIF(D:D,"<="&$I2)/$G$7 -> 0
A3: 700 | B3: 2400 | C3: 4200 | D3: 6000 | F3: сред | G3: =AVERAGE(A:D) -> 4706.5934 | I3: 400 | J3: =COUNTIF(A:A,">="&$I3)/$G$7 -> 0.97802198 | K3: =COUNTIF(B:B,">="&$I3)/$G$7 -> 1 | L3: =COUNTIF(C:C,"<="&$I3)/$G$7 -> 0 | M3: =COUNTIF(D:D,"<="&$I3)/$G$7 -> 0
A4: 800 | B4: 2200 | C4: 4800 | D4: 7500 | F4: медиана | G4: =MEDIAN(A:D) -> 3400 | I4: 500 | J4: =COUNTIF(A:A,">="&$I4)/$G$7 -> 0.88461538 | K4: =COUNTIF(B:B,">="&$I4)/$G$7 -> 1 | L4: =COUNTIF(C:C,"<="&$I4)/$G$7 -> 0 | M4: =COUNTIF(D:D,"<="&$I4)/$G$7 -> 0
A5: 2000 | B5: 6000 | C5: 14100 | D5: 24500 | I5: 600 | J5: =COUNTIF(A:A,">="&$I5)/$G$7 -> 0.79395604 | K5: =COUNTIF(B:B,">="&$I5)/$G$7 -> 1 | L5: =COUNTIF(C:C,"<="&$I5)/$G$7 -> 0 | M5: =COUNTIF(D:D,"<="&$I5)/$G$7 -> 0
A6: 1400 | B6: 3800 | C6: 6900 | D6: 11500 | I6: 700 | J6: =COUNTIF(A:A,">="&$I6)/$G$7 -> 0.65934066 | K6: =COUNTIF(B:B,">="&$I6)/$G$7 -> 1 | L6: =COUNTIF(C:C,"<="&$I6)/$G$7 -> 0 | M6: =COUNTIF(D:D,"<="&$I6)/$G$7 -> 0
A7: 600 | B7: 1400 | C7: 3000 | D7: 5000 | F7: респонденты | G7: =COUNT(A:A) -> 364 | I7: 800 | J7: =COUNTIF(A:A,">="&$I7)/$G$7 -> 0.59065934 | K7: =COUNTIF(B:B,">="&$I7)/$G$7 -> 1 | L7: =COUNTIF(C:C,"<="&$I7)/$G$7 -> 0 | M7: =COUNTIF(D:D,"<="&$I7)/$G$7 -> 0
A8: 1400 | B8: 3800 | C8: 6900 | D8: 13000 | I8: 900 | J8: =COUNTIF(A:A,">="&$I8)/$G$7 -> 0.49175824 | K8: =COUNTIF(B:B,">="&$I8)/$G$7 -> 0.96703297 | L8: =COUNTIF(C:C,"<="&$I8)/$G$7 -> 0 | M8: =COUNTIF(D:D,"<="&$I8)/$G$7 -> 0
A9: 1400 | B9: 3600 | C9: 7200 | D9: 12500 | I9: 1000 | J9: =COUNTIF(A:A,">="&$I9)/$G$7 -> 0.34340659 | K9: =COUNTIF(B:B,">="&$I9)/$G$7 -> 0.96703297 | L9: =COUNTIF(C:C,"<="&$I9)/$G$7 -> 0 | M9: =COUNTIF(D:D,"<="&$I9)/$G$7 -> 0
A10: 800 | B10: 1800 | C10: 4800 | D10: 6500 | I10: 1100 | J10: =COUNTIF(A:A,">="&$I10)/$G$7 -> 0.27197802 | K10: =COUNTIF(B:B,">="&$I10)/$G$7 -> 0.90934066 | L10: =COUNTIF(C:C,"<="&$I10)/$G$7 -> 0 | M10: =COUNTIF(D:D,"<="&$I10)/$G$7 -> 0
A11: 500 | B11: 2000 | C11: 3900 | D11: 7500 | I11: 1200 | J11: =COUNTIF(A:A,">="&$I11)/$G$7 -> 0.24450549 | K11: =COUNTIF(B:B,">="&$I11)/$G$7 -> 0.90934066 | L11: =COUNTIF(C:C,"<="&$I11)/$G$7 -> 0 | M11: =COUNTIF(D:D,"<="&$I11)/$G$7 -> 0
A12: 2500 | B12: 6600 | C12: 13200 | D12: 22000 | I12: 1300 | J12: =COUNTIF(A:A,">="&$I12)/$G$7 -> 0.21978022 | K12: =COUNTIF(B:B,">="&$I12)/$G$7 -> 0.8543956 | L12: =COUNTIF(C:C,"<="&$I12)/$G$7 -> 0 | M12: =COUNTIF(D:D,"<="&$I12)/$G$7 -> 0
A13: 900 | B13: 2000 | C13: 3900 | D13: 7000 | I13: 1400 | J13: =COUNTIF(A:A,">="&$I13)/$G$7 -> 0.18406593 | K13: =COUNTIF(B:B,">="&$I13)/$G$7 -> 0.8543956 | L13: =COUNTIF(C:C,"<="&$I13)/$G$7 -> 0 | M13: =COUNTIF(D:D,"<="&$I13)/$G$7 -> 0
A14: 800 | B14: 3000 | C14: 8400 | D14: 12500 | I14: 1500 | J14: =COUNTIF(A:A,">="&$I14)/$G$7 -> 0.13461538 | K14: =COUNTIF(B:B,">="&$I14)/$G$7 -> 0.78021978 | L14: =COUNTIF(C:C,"<="&$I14)/$G$7 -> 0 | M14: =COUNTIF(D:D,"<="&$I14)/$G$7 -> 0
A15: 900 | B15: 3400 | C15: 8400 | D15: 10500 | I15: 1600 | J15: =COUNTIF(A:A,">="&$I15)/$G$7 -> 0.1043956 | K15: =COUNTIF(B:B,">="&$I15)/$G$7 -> 0.78021978 | L15: =COUNTIF(C:C,"<="&$I15)/$G$7 -> 0 | M15: =COUNTIF(D:D,"<="&$I15)/$G$7 -> 0
A16: 1000 | B16: 2000 | C16: 4200 | D16: 7500 | I16: 1700 | J16: =COUNTIF(A:A,">="&$I16)/$G$7 -> 0.1043956 | K16: =COUNTIF(B:B,">="&$I16)/$G$7 -> 0.68956044 | L16: =COUNTIF(C:C,"<="&$I16)/$G$7 -> 0 | M16: =COUNTIF(D:D,"<="&$I16)/$G$7 -> 0
A17: 400 | B17: 2000 | C17: 3000 | D17: 5500 | I17: 1800 | J17: =COUNTIF(A:A,">="&$I17)/$G$7 -> 0.1043956 | K17: =COUNTIF(B:B,">="&$I17)/$G$7 -> 0.68956044 | L17: =COUNTIF(C:C,"<="&$I17)/$G$7 -> 0 | M17: =COUNTIF(D:D,"<="&$I17)/$G$7 -> 0
A18: 2900 | B18: 5600 | C18: 13500 | D18: 24000 | I18: 1900 | J18: =COUNTIF(A:A,">="&$I18)/$G$7 -> 0.1043956 | K18: =COUNTIF(B:B,">="&$I18)/$G$7 -> 0.60164835 | L18: =COUNTIF(C:C,"<="&$I18)/$G$7 -> 0 | M18: =COUNTIF(D:D,"<="&$I18)/$G$7 -> 0
A19: 900 | B19: 2200 | C19: 3600 | D19: 7500 | I19: 2000 | J19: =COUNTIF(A:A,">="&$I19)/$G$7 -> 0.1043956 | K19: =COUNTIF(B:B,">="&$I19)/$G$7 -> 0.60164835 | L19: =COUNTIF(C:C,"<="&$I19)/$G$7 -> 0 | M19: =COUNTIF(D:D,"<="&$I19)/$G$7 -> 0
... A99: 300 | B99: 1600 | C99: 3000 | D99: 6000 | I99: 10000 | J99: =COUNTIF(A:A,">="&$I99)/$G$7 -> 0 | K99: =COUNTIF(B:B,">="&$I99)/$G$7 -> 0 | L99: =COUNTIF(C:C,"<="&$I99)/$G$7 -> 0.8956044 | M99: =COUNTIF(D:D,"<="&$I99)/$G$7 -> 0.62912088
A100: 500 | B100: 1400 | C100: 2400 | D100: 4000
A101: 900 | B101: 1600 | C101: 4500 | D101: 8000
A102: 1000 | B102: 1800 | C102: 4500 | D102: 6000
A103: 1300 | B103: 3200 | C103: 6600 | D103: 11500
A104: 900 | B104: 2200 | C104: 5100 | D104: 6500
A105: 500 | B105: 1600 | C105: 4800 | D105: 8000
A106: 500 | B106: 1000 | C106: 2700 | D106: 5000
A107: 700 | B107: 2000 | C107: 3900 | D107: 8000
A108: 900 | B108: 2000 | C108: 3600 | D108: 6000
A109: 700 | B109: 1600 | C109: 3300 | D109: 7000
A110: 2300 | B110: 8000 | C110: 12300 | D110: 21500
A111: 1400 | B111: 3800 | C111: 8400 | D111: 11000
... A365: 1300 | B365: 3000 | C365: 8700 | D365: 12000

Sheet 4 способ
A1: сл. Дешево | B1: Дешево | C1: Дорого | D1: Сл.Дорого | F1: Названия строк | G1: Количество по полю сл. Дешево | I1: Названия строк | J1: Количество по полю Дешево | L1: Названия строк | M1: Количество по полю Дорого | O1: Названия строк | P1: Количество по полю Сл.Дорого
A2: 1500 | B2: 3800 | C2: 8700 | D2: 16500 | F2: 2500 | G2: 0.0047169811 | I2: 6000 | J2: 0.0047169811 | L2: 2400 | M2: 0.0078616352 | O2: 4000 | P2: 0.033018868
A3: 2000 | B3: 4000 | C3: 9900 | D3: 20000 | F3: 2400 | G3: 0.02672956 | I3: 5800 | J3: 0.020440252 | L3: 2700 | M3: 0.081761006 | O3: 4500 | P3: 0.086477987
A4: 800 | B4: 1800 | C4: 2700 | D4: 4500 | F4: 2300 | G4: 0.050314465 | I4: 5600 | J4: 0.04245283 | L4: 3000 | M4: 0.13679245 | O4: 5000 | P4: 0.13050314
A5: 1800 | B5: 3800 | C5: 8400 | D5: 14500 | F5: 2200 | G5: 0.059748428 | I5: 5400 | J5: 0.081761006 | L5: 3300 | M5: 0.18553459 | O5: 5500 | P5: 0.16509434
A6: 1400 | B6: 4600 | C6: 7500 | D6: 13500 | F6: 2100 | G6: 0.075471698 | I6: 5200 | J6: 0.11792453 | L6: 3600 | M6: 0.19025157 | O6: 6000 | P6: 0.19025157
A7: 2000 | B7: 3600 | C7: 8400 | D7: 13000 | F7: 2000 | G7: 0.11006289 | I7: 5000 | J7: 0.18081761 | L7: 3900 | M7: 0.1918239 | O7: 7000 | P7: 0.20283019
A8: 800 | B8: 1800 | C8: 2700 | D8: 4000 | F8: 1900 | G8: 0.16509434 | I8: 4800 | J8: 0.24371069 | L8: 4200 | M8: 0.20440252 | O8: 7500 | P8: 0.22955975
A9: 1900 | B9: 4400 | C9: 9600 | D9: 18000 | F9: 1800 | G9: 0.22798742 | I9: 4600 | J9: 0.29874214 | L9: 4500 | M9: 0.22327044 | O9: 8000 | P9: 0.25471698
A10: 1300 | B10: 5000 | C10: 9900 | D10: 14500 | F10: 1700 | G10: 0.29716981 | I10: 4400 | J10: 0.36477987 | L10: 4800 | M10: 0.24842767 | O10: 8500 | P10: 0.27987421
A11: 1300 | B11: 3400 | C11: 9600 | D11: 14000 | F11: 1600 | G11: 0.36792453 | I11: 4200 | J11: 0.43710692 | L11: 5100 | M11: 0.27672956 | O11: 9000 | P11: 0.30188679
A12: 1100 | B12: 5000 | C12: 7200 | D12: 12500 | F12: 1500 | G12: 0.41823899 | I12: 4000 | J12: 0.49842767 | L12: 5400 | M12: 0.30188679 | O12: 9500 | P12: 0.33176101
A13: 1800 | B13: 5000 | C13: 8100 | D13: 14000 | F13: 1400 | G13: 0.47169811 | I13: 3800 | J13: 0.54874214 | L13: 5700 | M13: 0.3254717 | O13: 10000 | P13: 0.34119497
... A23: 800 | B23: 1600 | C23: 2700 | D23: 5500 | F23: 400 | G23: 1 | I23: 1400 | J23: 0.93238994 | L23: 9600 | M23: 0.74685535 | O23: 16500 | P23: 0.8254717
A24: 1000 | B24: 3200 | C24: 7500 | D24: 13000 | I24: 1200 | J24: 0.97955975 | L24: 9900 | M24: 0.80974843 | O24: 17000 | P24: 0.85691824
A25: 1100 | B25: 3800 | C25: 8700 | D25: 15000 | I25: 1000 | J25: 1 | L25: 10200 | M25: 0.84433962 | O25: 17500 | P25: 0.90251572
A26: 1400 | B26: 4400 | C26: 10500 | D26: 18000 | L26: 10500 | M26: 0.89150943 | O26: 18000 | P26: 0.9418239
A27: 1000 | B27: 2000 | C27: 5400 | D27: 8000 | L27: 10800 | M27: 0.93081761 | O27: 18500 | P27: 0.95440252
A28: 2000 | B28: 5200 | C28: 9600 | D28: 16000 | L28: 11100 | M28: 0.95440252 | O28: 19000 | P28: 0.96855346
A29: 1800 | B29: 4200 | C29: 7800 | D29: 14500 | L29: 11400 | M29: 0.9827044 | O29: 19500 | P29: 0.98899371
A30: 1300 | B30: 4400 | C30: 10800 | D30: 15000 | L30: 11700 | M30: 0.99528302 | O30: 20000 | P30: 1
A31: 700 | B31: 2400 | C31: 5100 | D31: 8500 | L31: 12000 | M31: 1
A32: 800 | B32: 2200 | C32: 6000 | D32: 8500
A33: 600 | B33: 1200 | C33: 3300 | D33: 5000
A34: 600 | B34: 1600 | C34: 3000 | D34: 5000
A35: 1600 | B35: 4000 | C35: 8700 | D35: 14000
A36: 2000 | B36: 5200 | C36: 11700 | D36: 17500
A37: 1900 | B37: 5200 | C37: 8400 | D37: 14000
A38: 1500 | B38: 3600 | C38: 10500 | D38: 13500
A39: 700 | B39: 1400 | C39: 2700 | D39: 5500
A40: 1000 | B40: 4800 | C40: 8700 | D40: 15000
A41: 1600 | B41: 4400 | C41: 8100 | D41: 14000
A42: 900 | B42: 2000 | C42: 4200 | D42: 8000
A43: 800 | B43: 2400 | C43: 6000 | D43: 7500
... A637: 1000 | B637: 3800 | C637: 10200 | D637: 14000
