Workbook

Sheet Данные
A1: ФИО менеджера | B1: ФИО клиента | C1: Дата сделки | D1: Сумма сделки | E1: NPS
A2: Ткаченко Андрей Олегович | B2: Лебедев Павел Кириллович | C2: 2023-09-01 | D2: 63205 | E2: 8
A3: Белов Алексей Константинович | B3: Попова Ольга Егоровна | C3: 2023-09-01 | D3: 38636 | E3: 8
A4: Новикова Ольга Петровна | B4: Попова Екатерина Владимировна | C4: 2023-09-01 | D4: 67204 | E4: 6
A5: Сидорова Елена Васильевна | B5: Сидоров Артем Викторович | C5: 2023-09-04 | D5: 84220 | E5: 9
A6: Громова Мария Ильинична | B6: Новиков Алексей Александрович | C6: 2023-09-04 | D6: 78490 | E6: 7
A7: Орлов Павел Денисович | B7: Сидорова Полина Александровна | C7: 2023-09-04 | D7: 58851 | E7: 5
A8: Белов Алексей Константинович | B8: Егорова Полина Сергеевна | C8: 2023-09-04 | D8: 52764 | E8: 8
A9: Новикова Ольга Петровна | B9: Смирнов Дмитрий Александрович | C9: 2023-09-05 | D9: 91862 | E9: 8
A10: Новикова Ольга Петровна | B10: Волкова Татьяна Егоровна | C10: 2023-09-05 | D10: 40540 | E10: 7
A11: Кузнецов Дмитрий Львович | B11: Петрова Дарья Егоровна | C11: 2023-09-05 | D11: 67289 | E11: 5
A12: Сидорова Елена Васильевна | B12: Смирнова София Ивановна | C12: 2023-09-06 | D12: 19382 | E12: 2
A13: Фролов Сергей Викторович | B13: Смирнов Михаил Алексеевич | C13: 2023-09-06 | D13: 38637 | E13: 5
... A1001: Ткаченко Андрей Олегович | B1001: Иванова Александра Никитична | C1001: 2024-09-02 | D1001: 72906 | E1001: 7

Sheet задача 1
A1: ФИО менеджера | D1: ФИО менеджера | E1: ФИО клиента | F1: первый проект | G1: последний проект | H1: дни | J1: менеджер клиент | K1: ФИО менеджера | L1: ФИО клиента | M1: Дата сделки | N1: менеджер и клиент | O1: ФИО менеджера | P1: ФИО клиента | Q1: Дата сделки
A2: Белов Алексей Константинович | D2: Белов Алексей Константинович | E2: Алексеева Алиса Ильинична | F2: =VLOOKUP(D2&E2,J:M,4,0) -> 2024-02-08 | G2: =VLOOKUP(D2&E2,N:Q,4,0) -> 2024-02-08 | H2: =G2-F2 -> 0 | J2: =K2&L2 -> Ткаченко Андрей ОлеговичЛебедев Павел Кириллович | K2: Ткаченко Андрей Олегович | L2: Лебедев Павел Кириллович | M2: 2023-09-01 | N2: =O2&P2 -> Иванова Анна СергеевнаАлексеева Виктория Александровна | O2: Иванова Анна Сергеевна | P2: Алексеева Виктория Александровна | Q2: 2024-09-02
A3: Громова Мария Ильинична | D3: Белов Алексей Константинович | E3: Алексеева Виктория Александровна | F3: =VLOOKUP(D3&E3,J:M,4,0) -> 2024-05-20 | G3: =VLOOKUP(D3&E3,N:Q,4,0) -> 2024-05-20 | H3: =G3-F3 -> 0 | J3: =K3&L3 -> Белов Алексей КонстантиновичПопова Ольга Егоровна | K3: Белов Алексей Константинович | L3: Попова Ольга Егоровна | M3: 2023-09-01 | N3: =O3&P3 -> Иванова Анна СергеевнаСидоров Михаил Артемович | O3: Иванова Анна Сергеевна | P3: Сидоров Михаил Артемович | Q3: 2024-09-02
A4: Иванова Анна Сергеевна | D4: Белов Алексей Константинович | E4: Алексеева Людмила Никитична | F4: =VLOOKUP(D4&E4,J:M,4,0) -> 2023-11-27 | G4: =VLOOKUP(D4&E4,N:Q,4,0) -> 2023-11-27 | H4: =G4-F4 -> 0 | J4: =K4&L4 -> Новикова Ольга ПетровнаПопова Екатерина Владимировна | K4: Новикова Ольга Петровна | L4: Попова Екатерина Владимировна | M4: 2023-09-01 | N4: =O4&P4 -> Ткаченко Андрей ОлеговичИванова Александра Никитична | O4: Ткаченко Андрей Олегович | P4: Иванова Александра Никитична | Q4: 2024-09-02
A5: Кузнецов Дмитрий Львович | D5: Белов Алексей Константинович | E5: Васильев Александр Иванович | F5: =VLOOKUP(D5&E5,J:M,4,0) -> 2024-04-29 | G5: =VLOOKUP(D5&E5,N:Q,4,0) -> 2024-04-29 | H5: =G5-F5 -> 0 | J5: =K5&L5 -> Сидорова Елена ВасильевнаСидоров Артем Викторович | K5: Сидорова Елена Васильевна | L5: Сидоров Артем Викторович | M5: 2023-09-04 | N5: =O5&P5 -> Новикова Ольга ПетровнаСмирнов Дмитрий Александрович | O5: Новикова Ольга Петровна | P5: Смирнов Дмитрий Александрович | Q5: 2024-08-30
A6: Новикова Ольга Петровна | D6: Белов Алексей Константинович | E6: Васильев Егор Владимирович | F6: =VLOOKUP(D6&E6,J:M,4,0) -> 2024-06-05 | G6: =VLOOKUP(D6&E6,N:Q,4,0) -> 2024-06-05 | H6: =G6-F6 -> 0 | J6: =K6&L6 -> Громова Мария ИльиничнаНовиков Алексей Александрович | K6: Громова Мария Ильинична | L6: Новиков Алексей Александрович | M6: 2023-09-04 | N6: =O6&P6 -> Новикова Ольга ПетровнаФедорова Полина Павловна | O6: Новикова Ольга Петровна | P6: Федорова Полина Павловна | Q6: 2024-08-30
A7: Орлов Павел Денисович | D7: Белов Алексей Константинович | E7: Васильев Кирилл Михайлович | F7: =VLOOKUP(D7&E7,J:M,4,0) -> 2023-10-16 | G7: =VLOOKUP(D7&E7,N:Q,4,0) -> 2023-10-16 | H7: =G7-F7 -> 0 | J7: =K7&L7 -> Орлов Павел ДенисовичСидорова Полина Александровна | K7: Орлов Павел Денисович | L7: Сидорова Полина Александровна | M7: 2023-09-04 | N7: =O7&P7 -> Яковлев Артем ИгоревичКозлов Артур Андреевич | O7: Яковлев Артем Игоревич | P7: Козлов Артур Андреевич | Q7: 2024-08-30
A8: Петров Владимир Кириллович | D8: Белов Алексей Константинович | E8: Васильев Никита Викторович | F8: =VLOOKUP(D8&E8,J:M,4,0) -> 2023-10-26 | G8: =VLOOKUP(D8&E8,N:Q,4,0) -> 2024-01-30 | H8: =G8-F8 -> 96 | J8: =K8&L8 -> Белов Алексей КонстантиновичЕгорова Полина Сергеевна | K8: Белов Алексей Константинович | L8: Егорова Полина Сергеевна | M8: 2023-09-04 | N8: =O8&P8 -> Кузнецов Дмитрий ЛьвовичИванова Анна Викторовна | O8: Кузнецов Дмитрий Львович | P8: Иванова Анна Викторовна | Q8: 2024-08-29
A9: Семенова Ирина Валерьевна | D9: Белов Алексей Константинович | E9: Васильева Наталья Никитична | F9: =VLOOKUP(D9&E9,J:M,4,0) -> 2024-05-31 | G9: =VLOOKUP(D9&E9,N:Q,4,0) -> 2024-05-31 | H9: =G9-F9 -> 0 | J9: =K9&L9 -> Новикова Ольга ПетровнаСмирнов Дмитрий Александрович | K9: Новикова Ольга Петровна | L9: Смирнов Дмитрий Александрович | M9: 2023-09-05 | N9: =O9&P9 -> Орлов Павел ДенисовичПавлов Константин Никитич | O9: Орлов Павел Денисович | P9: Павлов Константин Никитич | Q9: 2024-08-29
A10: Сидорова Елена Васильевна | D10: Белов Алексей Константинович | E10: Васильева Татьяна Геннадьевна | F10: =VLOOKUP(D10&E10,J:M,4,0) -> 2023-12-27 | G10: =VLOOKUP(D10&E10,N:Q,4,0) -> 2023-12-27 | H10: =G10-F10 -> 0 | J10: =K10&L10 -> Новикова Ольга ПетровнаВолкова Татьяна Егоровна | K10: Новикова Ольга Петровна | L10: Волкова Татьяна Егоровна | M10: 2023-09-05 | N10: =O10&P10 -> Громова Мария ИльиничнаИванов Андрей Михайлович | O10: Громова Мария Ильинична | P10: Иванов Андрей Михайлович | Q10: 2024-08-29
A11: Ткаченко Андрей Олегович | D11: Белов Алексей Константинович | E11: Волков Роман Иванович | F11: =VLOOKUP(D11&E11,J:M,4,0) -> 2023-11-06 | G11: =VLOOKUP(D11&E11,N:Q,4,0) -> 2023-11-06 | H11: =G11-F11 -> 0 | J11: =K11&L11 -> Кузнецов Дмитрий ЛьвовичПетрова Дарья Егоровна | K11: Кузнецов Дмитрий Львович | L11: Петрова Дарья Егоровна | M11: 2023-09-05 | N11: =O11&P11 -> Ткаченко Андрей ОлеговичЛебедев Роман Станиславович | O11: Ткаченко Андрей Олегович | P11: Лебедев Роман Станиславович | Q11: 2024-08-29
A12: Фролов Сергей Викторович | D12: Белов Алексей Константинович | E12: Волкова Татьяна Егоровна | F12: =VLOOKUP(D12&E12,J:M,4,0) -> 2024-07-24 | G12: =VLOOKUP(D12&E12,N:Q,4,0) -> 2024-07-24 | H12: =G12-F12 -> 0 | J12: =K12&L12 -> Сидорова Елена ВасильевнаСмирнова София Ивановна | K12: Сидорова Елена Васильевна | L12: Смирнова София Ивановна | M12: 2023-09-06 | N12: =O12&P12 -> Кузнецов Дмитрий ЛьвовичФедорова Полина Павловна | O12: Кузнецов Дмитрий Львович | P12: Федорова Полина Павловна | Q12: 2024-08-29
A13: Яковлев Артем Игоревич | D13: Белов Алексей Константинович | E13: Егорова Полина Сергеевна | F13: =VLOOKUP(D13&E13,J:M,4,0) -> 2023-09-04 | G13: =VLOOKUP(D13&E13,N:Q,4,0) -> 2023-09-04 | H13: =G13-F13 -> 0 | J13: =K13&L13 -> Фролов Сергей ВикторовичСмирнов Михаил Алексеевич | K13: Фролов Сергей Викторович | L13: Смирнов Михаил Алексеевич | M13: 2023-09-06 | N13: =O13&P13 -> Иванова Анна СергеевнаИванова Анна Викторовна | O13: Иванова Анна Сергеевна | P13: Иванова Анна Викторовна | Q13: 2024-08-29
D14: Белов Алексей Константинович | E14: Иванов Владимир Романович | F14: =VLOOKUP(D14&E14,J:M,4,0) -> 2024-06-17 | G14: =VLOOKUP(D14&E14,N:Q,4,0) -> 2024-07-23 | H14: =G14-F14 -> 36 | J14: =K14&L14 -> Белов Алексей КонстантиновичПетрова Людмила Ильинична | K14: Белов Алексей Константинович | L14: Петрова Людмила Ильинична | M14: 2023-09-07 | N14: =O14&P14 -> Кузнецов Дмитрий ЛьвовичНиколаев Артур Никитич | O14: Кузнецов Дмитрий Львович | P14: Николаев Артур Никитич | Q14: 2024-08-28
D15: Белов Алексей Константинович | E15: Иванова Анна Викторовна | F15: =VLOOKUP(D15&E15,J:M,4,0) -> 2024-07-29 | G15: =VLOOKUP(D15&E15,N:Q,4,0) -> 2024-07-29 | H15: =G15-F15 -> 0 | J15: =K15&L15 -> Орлов Павел ДенисовичФедорова Наталья Александровна | K15: Орлов Павел Денисович | L15: Федорова Наталья Александровна | M15: 2023-09-07 | N15: =O15&P15 -> Яковлев Артем ИгоревичВасильева Наталья Никитична | O15: Яковлев Артем Игоревич | P15: Васильева Наталья Никитична | Q15: 2024-08-27
D16: Белов Алексей Константинович | E16: Козлов Артур Андреевич | F16: =VLOOKUP(D16&E16,J:M,4,0) -> 2024-01-08 | G16: =VLOOKUP(D16&E16,N:Q,4,0) -> 2024-01-08 | H16: =G16-F16 -> 0 | J16: =K16&L16 -> Белов Алексей КонстантиновичМорозов Дмитрий Кириллович | K16: Белов Алексей Константинович | L16: Морозов Дмитрий Кириллович | M16: 2023-09-08 | N16: =O16&P16 -> Семенова Ирина ВалерьевнаВасильев Кирилл Михайлович | O16: Семенова Ирина Валерьевна | P16: Васильев Кирилл Михайлович | Q16: 2024-08-27
D17: Белов Алексей Константинович | E17: Кузнецова Валерия Романовна | F17: =VLOOKUP(D17&E17,J:M,4,0) -> 2023-09-19 | G17: =VLOOKUP(D17&E17,N:Q,4,0) -> 2023-09-19 | H17: =G17-F17 -> 0 | J17: =K17&L17 -> Ткаченко Андрей ОлеговичОрлова Александра Викторовна | K17: Ткаченко Андрей Олегович | L17: Орлова Александра Викторовна | M17: 2023-09-08 | N17: =O17&P17 -> Ткаченко Андрей ОлеговичВасильева Мария Дмитриевна | O17: Ткаченко Андрей Олегович | P17: Васильева Мария Дмитриевна | Q17: 2024-08-27
D18: Белов Алексей Константинович | E18: Кузнецова Ксения Кирилловна | F18: =VLOOKUP(D18&E18,J:M,4,0) -> 2023-10-09 | G18: =VLOOKUP(D18&E18,N:Q,4,0) -> 2023-10-09 | H18: =G18-F18 -> 0 | J18: =K18&L18 -> Сидорова Елена ВасильевнаКозлов Дмитрий Викторович | K18: Сидорова Елена Васильевна | L18: Козлов Дмитрий Викторович | M18: 2023-09-08 | N18: =O18&P18 -> Орлов Павел ДенисовичПопов Дмитрий Ильич | O18: Орлов Павел Денисович | P18: Попов Дмитрий Ильич | Q18: 2024-08-27
D19: Белов Алексей Константинович | E19: Лебедев Артур Олегович | F19: =VLOOKUP(D19&E19,J:M,4,0) -> 2024-04-08 | G19: =VLOOKUP(D19&E19,N:Q,4,0) -> 2024-04-08 | H19: =G19-F19 -> 0 | J19: =K19&L19 -> Петров Владимир КирилловичВасильева Татьяна Геннадьевна | K19: Петров Владимир Кириллович | L19: Васильева Татьяна Геннадьевна | M19: 2023-09-08 | N19: =O19&P19 -> Фролов Сергей ВикторовичПетров Алексей Артемович | O19: Фролов Сергей Викторович | P19: Петров Алексей Артемович | Q19: 2024-08-26
D20: Белов Алексей Константинович | E20: Лебедев Сергей Иванович | F20: =VLOOKUP(D20&E20,J:M,4,0) -> 2023-09-28 | G20: =VLOOKUP(D20&E20,N:Q,4,0) -> 2023-09-28 | H20: =G20-F20 -> 0 | J20: =K20&L20 -> Кузнецов Дмитрий ЛьвовичЛебедева Полина Артемовна | K20: Кузнецов Дмитрий Львович | L20: Лебедева Полина Артемовна | M20: 2023-09-08 | N20: =O20&P20 -> Фролов Сергей ВикторовичВолкова Наталья Александровна | O20: Фролов Сергей Викторович | P20: Волкова Наталья Александровна | Q20: 2024-08-26
D21: Белов Алексей Константинович | E21: Морозов Андрей Иванович | F21: =VLOOKUP(D21&E21,J:M,4,0) -> 2023-09-25 | G21: =VLOOKUP(D21&E21,N:Q,4,0) -> 2023-09-25 | H21: =G21-F21 -> 0 | J21: =K21&L21 -> Сидорова Елена ВасильевнаЕгоров Георгий Никитич | K21: Сидорова Елена Васильевна | L21: Егоров Георгий Никитич | M21: 2023-09-08 | N21: =O21&P21 -> Орлов Павел ДенисовичСеменов Дмитрий Павлович | O21: Орлов Павел Денисович | P21: Семенов Дмитрий Павлович | Q21: 2024-08-26
D22: Белов Алексей Константинович | E22: Морозов Дмитрий Кириллович | F22: =VLOOKUP(D22&E22,J:M,4,0) -> 2023-09-08 | G22: =VLOOKUP(D22&E22,N:Q,4,0) -> 2024-05-03 | H22: =G22-F22 -> 238 | J22: =K22&L22 -> Новикова Ольга ПетровнаВолкова Виктория Михайловна | K22: Новикова Ольга Петровна | L22: Волкова Виктория Михайловна | M22: 2023-09-08 | N22: =O22&P22 -> Новикова Ольга ПетровнаИванова Анна Викторовна | O22: Новикова Ольга Петровна | P22: Иванова Анна Викторовна | Q22: 2024-08-26
D23: Белов Алексей Константинович | E23: Морозов Никита Иванович | F23: =VLOOKUP(D23&E23,J:M,4,0) -> 2024-03-21 | G23: =VLOOKUP(D23&E23,N:Q,4,0) -> 2024-03-21 | H23: =G23-F23 -> 0 | J23: =K23&L23 -> Ткаченко Андрей ОлеговичСтепанов Дмитрий Владимирович | K23: Ткаченко Андрей Олегович | L23: Степанов Дмитрий Владимирович | M23: 2023-09-11 | N23: =O23&P23 -> Яковлев Артем ИгоревичПетрова София Алексеевна | O23: Яковлев Артем Игоревич | P23: Петрова София Алексеевна | Q23: 2024-08-26
D24: Белов Алексей Константинович | E24: Морозов Сергей Олегович | F24: =VLOOKUP(D24&E24,J:M,4,0) -> 2024-03-18 | G24: =VLOOKUP(D24&E24,N:Q,4,0) -> 2024-03-18 | H24: =G24-F24 -> 0 | J24: =K24&L24 -> Фролов Сергей ВикторовичСтепанова Виктория Алексеевна | K24: Фролов Сергей Викторович | L24: Степанова Виктория Алексеевна | M24: 2023-09-11 | N24: =O24&P24 -> Кузнецов Дмитрий ЛьвовичЛебедева Полина Артемовна | O24: Кузнецов Дмитрий Львович | P24: Лебедева Полина Артемовна | Q24: 2024-08-26
D25: Белов Алексей Константинович | E25: Морозова Светлана Михайловна | F25: =VLOOKUP(D25&E25,J:M,4,0) -> 2023-11-24 | G25: =VLOOKUP(D25&E25,N:Q,4,0) -> 2023-11-24 | H25: =G25-F25 -> 0 | J25: =K25&L25 -> Ткаченко Андрей ОлеговичМорозова Людмила Юрьевна | K25: Ткаченко Андрей Олегович | L25: Морозова Людмила Юрьевна | M25: 2023-09-11 | N25: =O25&P25 -> Иванова Анна СергеевнаСеменов Андрей Кириллович | O25: Иванова Анна Сергеевна | P25: Семенов Андрей Кириллович | Q25: 2024-08-26
... D800: Яковлев Артем Игоревич | E800: Федорова Татьяна Никитична | F800: =VLOOKUP(D800&E800,J:M,4,0) -> 2024-08-05 | G800: =VLOOKUP(D800&E800,N:Q,4,0) -> 2024-08-05 | H800: =G800-F800 -> 0 | J800: =K800&L800 -> Петров Владимир КирилловичСтепанова Анна Никитична | K800: Петров Владимир Кириллович | L800: Степанова Анна Никитична | M800: 2024-06-24 | N800: =O800&P800 -> Громова Мария ИльиничнаКузнецов Георгий Никитич | O800: Громова Мария Ильинична | P800: Кузнецов Георгий Никитич | Q800: 2023-11-20
J801: =K801&L801 -> Семенова Ирина ВалерьевнаНовикова Дарья Викторовна | K801: Семенова Ирина Валерьевна | L801: Новикова Дарья Викторовна | M801: 2024-06-24 | N801: =O801&P801 -> Кузнецов Дмитрий ЛьвовичНовикова Дарья Викторовна | O801: Кузнецов Дмитрий Львович | P801: Новикова Дарья Викторовна | Q801: 2023-11-20
J802: =K802&L802 -> Ткаченко Андрей ОлеговичАлексеева Виктория Александровна | K802: Ткаченко Андрей Олегович | L802: Алексеева Виктория Александровна | M802: 2024-06-24 | N802: =O802&P802 -> Иванова Анна СергеевнаЕгоров Никита Геннадьевич | O802: Иванова Анна Сергеевна | P802: Егоров Никита Геннадьевич | Q802: 2023-11-17
J803: =K803&L803 -> Петров Владимир КирилловичИванов Владимир Романович | K803: Петров Владимир Кириллович | L803: Иванов Владимир Романович | M803: 2024-06-24 | N803: =O803&P803 -> Семенова Ирина ВалерьевнаМорозов Андрей Александрович | O803: Семенова Ирина Валерьевна | P803: Морозов Андрей Александрович | Q803: 2023-11-17
J804: =K804&L804 -> Новикова Ольга ПетровнаЛебедев Павел Кириллович | K804: Новикова Ольга Петровна | L804: Лебедев Павел Кириллович | M804: 2024-06-24 | N804: =O804&P804 -> Кузнецов Дмитрий ЛьвовичКузнецов Георгий Никитич | O804: Кузнецов Дмитрий Львович | P804: Кузнецов Георгий Никитич | Q804: 2023-11-17
J805: =K805&L805 -> Фролов Сергей ВикторовичПетров Максим Александрович | K805: Фролов Сергей Викторович | L805: Петров Максим Александрович | M805: 2024-06-25 | N805: =O805&P805 -> Петров Владимир КирилловичВолкова Валерия Олеговна | O805: Петров Владимир Кириллович | P805: Волкова Валерия Олеговна | Q805: 2023-11-16
J806: =K806&L806 -> Яковлев Артем ИгоревичФедорова Алиса Кирилловна | K806: Яковлев Артем Игоревич | L806: Федорова Алиса Кирилловна | M806: 2024-06-26 | N806: =O806&P806 -> Кузнецов Дмитрий ЛьвовичАлексеева Ксения Андреевна | O806: Кузнецов Дмитрий Львович | P806: Алексеева Ксения Андреевна | Q806: 2023-11-16
J807: =K807&L807 -> Кузнецов Дмитрий ЛьвовичМорозов Константин Романович | K807: Кузнецов Дмитрий Львович | L807: Морозов Константин Романович | M807: 2024-06-26 | N807: =O807&P807 -> Семенова Ирина ВалерьевнаПавлов Матвей Дмитриевич | O807: Семенова Ирина Валерьевна | P807: Павлов Матвей Дмитриевич | Q807: 2023-11-16
J808: =K808&L808 -> Яковлев Артем ИгоревичПавлова Ольга Юрьевна | K808: Яковлев Артем Игоревич | L808: Павлова Ольга Юрьевна | M808: 2024-06-26 | N808: =O808&P808 -> Яковлев Артем ИгоревичСидоров Михаил Артемович | O808: Яковлев Артем Игоревич | P808: Сидоров Михаил Артемович | Q808: 2023-11-16
J809: =K809&L809 -> Семенова Ирина ВалерьевнаКозлов Алексей Иванович | K809: Семенова Ирина Валерьевна | L809: Козлов Алексей Иванович | M809: 2024-06-27 | N809: =O809&P809 -> Иванова Анна СергеевнаИванова Ксения Романовна | O809: Иванова Анна Сергеевна | P809: Иванова Ксения Романовна | Q809: 2023-11-16
J810: =K810&L810 -> Семенова Ирина ВалерьевнаКузнецов Никита Сергеевич | K810: Семенова Ирина Валерьевна | L810: Кузнецов Никита Сергеевич | M810: 2024-06-27 | N810: =O810&P810 -> Семенова Ирина ВалерьевнаПавлов Роман Александрович | O810: Семенова Ирина Валерьевна | P810: Павлов Роман Александрович | Q810: 2023-11-14
J811: =K811&L811 -> Ткаченко Андрей ОлеговичСмирнов Кирилл Сергеевич | K811: Ткаченко Андрей Олегович | L811: Смирнов Кирилл Сергеевич | M811: 2024-06-27 | N811: =O811&P811 -> Белов Алексей КонстантиновичСмирнов Дмитрий Александрович | O811: Белов Алексей Константинович | P811: Смирнов Дмитрий Александрович | Q811: 2023-11-13
J812: =K812&L812 -> Громова Мария ИльиничнаФедорова Вероника Ивановна | K812: Громова Мария Ильинична | L812: Федорова Вероника Ивановна | M812: 2024-06-28 | N812: =O812&P812 -> Кузнецов Дмитрий ЛьвовичСмирнов Кирилл Сергеевич | O812: Кузнецов Дмитрий Львович | P812: Смирнов Кирилл Сергеевич | Q812: 2023-11-13
... J1001: =K1001&L1001 -> Ткаченко Андрей ОлеговичИванова Александра Никитична | K1001: Ткаченко Андрей Олегович | L1001: Иванова Александра Никитична | M1001: 2024-09-02 | N1001: =O1001&P1001 -> Новикова Ольга ПетровнаПопова Екатерина Владимировна | O1001: Новикова Ольга Петровна | P1001: Попова Екатерина Владимировна | Q1001: 2023-09-01

Sheet задача 1.1
A1: ФИО менеджера | B1: ФИО клиента | C1: первый проект | D1: последний проект | E1: дни
A2: Новикова Ольга Петровна | B2: Смирнов Дмитрий Александрович | C2: 2023-09-05 | D2: 2024-08-30 | E2: 360
A3: Кузнецов Дмитрий Львович | B3: Лебедева Полина Артемовна | C3: 2023-09-08 | D3: 2024-08-26 | E3: 353
A4: Яковлев Артем Игоревич | B4: Козлов Артур Андреевич | C4: 2023-09-15 | D4: 2024-08-30 | E4: 350
A5: Семенова Ирина Валерьевна | B5: Николаева Ирина Владимировна | C5: 2023-09-18 | D5: 2024-08-21 | E5: 338
A6: Кузнецов Дмитрий Львович | B6: Николаев Артур Никитич | C6: 2023-10-11 | D6: 2024-08-28 | E6: 322
A7: Новикова Ольга Петровна | B7: Орлов Максим Егорович | C7: 2023-10-10 | D7: 2024-08-23 | E7: 318
A8: Фролов Сергей Викторович | B8: Петров Алексей Артемович | C8: 2023-10-23 | D8: 2024-08-26 | E8: 308
A9: Фролов Сергей Викторович | B9: Степанова Виктория Алексеевна | C9: 2023-09-11 | D9: 2024-07-08 | E9: 301
A10: Кузнецов Дмитрий Львович | B10: Павлова Екатерина Павловна | C10: 2023-10-04 | D10: 2024-07-19 | E10: 289
A11: Семенова Ирина Валерьевна | B11: Васильев Никита Викторович | C11: 2023-09-11 | D11: 2024-06-24 | E11: 287
A12: Семенова Ирина Валерьевна | B12: Алексеева Екатерина Станиславовна | C12: 2023-10-10 | D12: 2024-07-16 | E12: 280
A13: Фролов Сергей Викторович | B13: Попова Александра Юрьевна | C13: 2023-10-09 | D13: 2024-07-15 | E13: 280
... A800: Яковлев Артем Игоревич | B800: Федорова Татьяна Никитична | C800: 2024-08-05 | D800: 2024-08-05 | E800: 0

Sheet задача 2
A1: ФИО клиента | B1: проекты | C1: сумма | D1: менеджеры
A2: Алексеев Алексей Павлович | B2: =COUNTIF(Данные!B:B,'задача 2'!A182) -> 7 | C2: =SUMIF(Данные!B:B,'задача 2'!A182,Данные!D:D) -> 335743 | D2: =COUNTIF('задача 1'!E:E,'задача 2'!A195) -> 2
A3: Алексеев Андрей Кириллович | B3: =COUNTIF(Данные!B:B,'задача 2'!A180) -> 3 | C3: =SUMIF(Данные!B:B,'задача 2'!A180,Данные!D:D) -> 242035 | D3: =COUNTIF('задача 1'!E:E,'задача 2'!A171) -> 6
A4: Алексеев Дмитрий Станиславович | B4: =COUNTIF(Данные!B:B,'задача 2'!A195) -> 3 | C4: =SUMIF(Данные!B:B,'задача 2'!A195,Данные!D:D) -> 140055 | D4: =COUNTIF('задача 1'!E:E,'задача 2'!A181) -> 5
A5: Алексеев Матвей Кириллович | B5: =COUNTIF(Данные!B:B,'задача 2'!A60) -> 9 | C5: =SUMIF(Данные!B:B,'задача 2'!A60,Данные!D:D) -> 532398 | D5: =COUNTIF('задача 1'!E:E,'задача 2'!A175) -> 5
A6: Алексеев Павел Дмитриевич | B6: =COUNTIF(Данные!B:B,'задача 2'!A111) -> 6 | C6: =SUMIF(Данные!B:B,'задача 2'!A111,Данные!D:D) -> 240041 | D6: =COUNTIF('задача 1'!E:E,'задача 2'!A166) -> 5
A7: Алексеева Алиса Александровна | B7: =COUNTIF(Данные!B:B,'задача 2'!A57) -> 8 | C7: =SUMIF(Данные!B:B,'задача 2'!A57,Данные!D:D) -> 490244 | D7: =COUNTIF('задача 1'!E:E,'задача 2'!A97) -> 8
A8: Алексеева Алиса Ильинична | B8: =COUNTIF(Данные!B:B,'задача 2'!A38) -> 4 | C8: =SUMIF(Данные!B:B,'задача 2'!A38,Данные!D:D) -> 193905 | D8: =COUNTIF('задача 1'!E:E,'задача 2'!A29) -> 4
A9: Алексеева Виктория Александровна | B9: =COUNTIF(Данные!B:B,'задача 2'!A126) -> 7 | C9: =SUMIF(Данные!B:B,'задача 2'!A126,Данные!D:D) -> 355858 | D9: =COUNTIF('задача 1'!E:E,'задача 2'!A3) -> 2
A10: Алексеева Екатерина Станиславовна | B10: =COUNTIF(Данные!B:B,'задача 2'!A84) -> 3 | C10: =SUMIF(Данные!B:B,'задача 2'!A84,Данные!D:D) -> 168818 | D10: =COUNTIF('задача 1'!E:E,'задача 2'!A108) -> 3
A11: Алексеева Ксения Андреевна | B11: =COUNTIF(Данные!B:B,'задача 2'!A119) -> 3 | C11: =SUMIF(Данные!B:B,'задача 2'!A119,Данные!D:D) -> 143648 | D11: =COUNTIF('задача 1'!E:E,'задача 2'!A46) -> 5
A12: Алексеева Людмила Никитична | B12: =COUNTIF(Данные!B:B,'задача 2'!A34) -> 5 | C12: =SUMIF(Данные!B:B,'задача 2'!A34,Данные!D:D) -> 245053 | D12: =COUNTIF('задача 1'!E:E,'задача 2'!A30) -> 4
A13: Алексеева Полина Станиславовна | B13: =COUNTIF(Данные!B:B,'задача 2'!A117) -> 6 | C13: =SUMIF(Данные!B:B,'задача 2'!A117,Данные!D:D) -> 319447 | D13: =COUNTIF('задача 1'!E:E,'задача 2'!A84) -> 3
A14: Васильев Александр Иванович | B14: =COUNTIF(Данные!B:B,'задача 2'!A105) -> 6 | C14: =SUMIF(Данные!B:B,'задача 2'!A105,Данные!D:D) -> 354666 | D14: =COUNTIF('задача 1'!E:E,'задача 2'!A78) -> 3
A15: Васильев Александр Никитич | B15: =COUNTIF(Данные!B:B,'задача 2'!A107) -> 4 | C15: =SUMIF(Данные!B:B,'задача 2'!A107,Данные!D:D) -> 231247 | D15: =COUNTIF('задача 1'!E:E,'задача 2'!A107) -> 3
A16: Васильев Артур Дмитриевич | B16: =COUNTIF(Данные!B:B,'задача 2'!A48) -> 1 | C16: =SUMIF(Данные!B:B,'задача 2'!A48,Данные!D:D) -> 44778 | D16: =COUNTIF('задача 1'!E:E,'задача 2'!A92) -> 3
A17: Васильев Георгий Станиславович | B17: =COUNTIF(Данные!B:B,'задача 2'!A150) -> 3 | C17: =SUMIF(Данные!B:B,'задача 2'!A150,Данные!D:D) -> 138663 | D17: =COUNTIF('задача 1'!E:E,'задача 2'!A88) -> 4
A18: Васильев Егор Владимирович | B18: =COUNTIF(Данные!B:B,'задача 2'!A98) -> 3 | C18: =SUMIF(Данные!B:B,'задача 2'!A98,Данные!D:D) -> 186899 | D18: =COUNTIF('задача 1'!E:E,'задача 2'!A94) -> 7
A19: Васильев Кирилл Михайлович | B19: =COUNTIF(Данные!B:B,'задача 2'!A62) -> 10 | C19: =SUMIF(Данные!B:B,'задача 2'!A62,Данные!D:D) -> 640224 | D19: =COUNTIF('задача 1'!E:E,'задача 2'!A111) -> 6
A20: Васильев Никита Викторович | B20: =COUNTIF(Данные!B:B,'задача 2'!A27) -> 4 | C20: =SUMIF(Данные!B:B,'задача 2'!A27,Данные!D:D) -> 166867 | D20: =COUNTIF('задача 1'!E:E,'задача 2'!A10) -> 2
A21: Васильева Алиса Дмитриевна | B21: =COUNTIF(Данные!B:B,'задача 2'!A137) -> 9 | C21: =SUMIF(Данные!B:B,'задача 2'!A137,Данные!D:D) -> 516701 | D21: =COUNTIF('задача 1'!E:E,'задача 2'!A135) -> 4
A22: Васильева Мария Дмитриевна | B22: =COUNTIF(Данные!B:B,'задача 2'!A176) -> 1 | C22: =SUMIF(Данные!B:B,'задача 2'!A176,Данные!D:D) -> 62932 | D22: =COUNTIF('задача 1'!E:E,'задача 2'!A139) -> 3
A23: Васильева Наталья Никитична | B23: =COUNTIF(Данные!B:B,'задача 2'!A77) -> 2 | C23: =SUMIF(Данные!B:B,'задача 2'!A77,Данные!D:D) -> 157880 | D23: =COUNTIF('задача 1'!E:E,'задача 2'!A18) -> 6
A24: Васильева Татьяна Геннадьевна | B24: =COUNTIF(Данные!B:B,'задача 2'!A19) -> 7 | C24: =SUMIF(Данные!B:B,'задача 2'!A19,Данные!D:D) -> 231064 | D24: =COUNTIF('задача 1'!E:E,'задача 2'!A50) -> 5
A25: Волков Алексей Артемович | B25: =COUNTIF(Данные!B:B,'задача 2'!A73) -> 7 | C25: =SUMIF(Данные!B:B,'задача 2'!A73,Данные!D:D) -> 420965 | D25: =COUNTIF('задача 1'!E:E,'задача 2'!A100) -> 1
A26: Волков Константин Алексеевич | B26: =COUNTIF(Данные!B:B,'задача 2'!A53) -> 1 | C26: =SUMIF(Данные!B:B,'задача 2'!A53,Данные!D:D) -> 24731 | D26: =COUNTIF('задача 1'!E:E,'задача 2'!A44) -> 3
A27: Волков Никита Кириллович | B27: =COUNTIF(Данные!B:B,'задача 2'!A149) -> 7 | C27: =SUMIF(Данные!B:B,'задача 2'!A149,Данные!D:D) -> 309026 | D27: =COUNTIF('задача 1'!E:E,'задача 2'!A150) -> 3
A28: Волков Роман Иванович | B28: =COUNTIF(Данные!B:B,'задача 2'!A47) -> 2 | C28: =SUMIF(Данные!B:B,'задача 2'!A47,Данные!D:D) -> 43227 | D28: =COUNTIF('задача 1'!E:E,'задача 2'!A12) -> 8
A29: Волкова Валерия Олеговна | B29: =COUNTIF(Данные!B:B,'задача 2'!A30) -> 5 | C29: =SUMIF(Данные!B:B,'задача 2'!A30,Данные!D:D) -> 174802 | D29: =COUNTIF('задача 1'!E:E,'задача 2'!A113) -> 4
A30: Волкова Виктория Михайловна | B30: =COUNTIF(Данные!B:B,'задача 2'!A22) -> 4 | C30: =SUMIF(Данные!B:B,'задача 2'!A22,Данные!D:D) -> 182307 | D30: =COUNTIF('задача 1'!E:E,'задача 2'!A146) -> 4
A31: Волкова Наталья Александровна | B31: =COUNTIF(Данные!B:B,'задача 2'!A76) -> 6 | C31: =SUMIF(Данные!B:B,'задача 2'!A76,Данные!D:D) -> 299260 | D31: =COUNTIF('задача 1'!E:E,'задача 2'!A51) -> 3
A32: Волкова София Андреевна | B32: =COUNTIF(Данные!B:B,'задача 2'!A192) -> 5 | C32: =SUMIF(Данные!B:B,'задача 2'!A192,Данные!D:D) -> 145387 | D32: =COUNTIF('задача 1'!E:E,'задача 2'!A192) -> 3
A33: Волкова Татьяна Егоровна | B33: =COUNTIF(Данные!B:B,'задача 2'!A10) -> 4 | C33: =SUMIF(Данные!B:B,'задача 2'!A10,Данные!D:D) -> 233442 | D33: =COUNTIF('задача 1'!E:E,'задача 2'!A81) -> 3
A34: Егоров Георгий Никитич | B34: =COUNTIF(Данные!B:B,'задача 2'!A21) -> 5 | C34: =SUMIF(Данные!B:B,'задача 2'!A21,Данные!D:D) -> 189879 | D34: =COUNTIF('задача 1'!E:E,'задача 2'!A96) -> 4
A35: Егоров Никита Геннадьевич | B35: =COUNTIF(Данные!B:B,'задача 2'!A87) -> 2 | C35: =SUMIF(Данные!B:B,'задача 2'!A87,Данные!D:D) -> 81982 | D35: =COUNTIF('задача 1'!E:E,'задача 2'!A105) -> 4
A36: Егорова Полина Сергеевна | B36: =COUNTIF(Данные!B:B,'задача 2'!A8) -> 8 | C36: =SUMIF(Данные!B:B,'задача 2'!A8,Данные!D:D) -> 453343 | D36: =COUNTIF('задача 1'!E:E,'задача 2'!A180) -> 3
A37: Иванов Андрей Михайлович | B37: =COUNTIF(Данные!B:B,'задача 2'!A142) -> 6 | C37: =SUMIF(Данные!B:B,'задача 2'!A142,Данные!D:D) -> 321273 | D37: =COUNTIF('задача 1'!E:E,'задача 2'!A62) -> 7
A38: Иванов Владимир Романович | B38: =COUNTIF(Данные!B:B,'задача 2'!A112) -> 9 | C38: =SUMIF(Данные!B:B,'задача 2'!A112,Данные!D:D) -> 469234 | D38: =COUNTIF('задача 1'!E:E,'задача 2'!A132) -> 6
A39: Иванов Роман Никитич | B39: =COUNTIF(Данные!B:B,'задача 2'!A140) -> 5 | C39: =SUMIF(Данные!B:B,'задача 2'!A140,Данные!D:D) -> 304586 | D39: =COUNTIF('задача 1'!E:E,'задача 2'!A125) -> 3
A40: Иванова Александра Никитична | B40: =COUNTIF(Данные!B:B,'задача 2'!A157) -> 1 | C40: =SUMIF(Данные!B:B,'задача 2'!A157,Данные!D:D) -> 53169 | D40: =COUNTIF('задача 1'!E:E,'задача 2'!A36) -> 2
...

Sheet задача 2.1
A1: ФИО клиента | B1: Дата сделки | C1: год | D1: месяц | E1: год-месяц | K1: ФИО клиента | L1: год-месяц | N1: ФИО клиента | O1: кол-во месяцев
A2: Лебедев Павел Кириллович | B2: 2023-09-01 | C2: =YEAR(B2) -> 2023 | D2: =MONTH(B2) -> 9 | E2: =C2&"-"&D2 -> 2023-9 | K2: Алексеев Алексей Павлович | L2: 2024-3 | N2: Николаева Ирина Владимировна | O2: =COUNTIF(K:K,N2) -> 11
A3: Попова Ольга Егоровна | B3: 2023-09-01 | C3: =YEAR(B3) -> 2023 | D3: =MONTH(B3) -> 9 | E3: =C3&"-"&D3 -> 2023-9 | K3: Алексеев Андрей Кириллович | L3: 2024-3 | N3: Васильев Никита Викторович | O3: =COUNTIF(K:K,N3) -> 9
A4: Попова Екатерина Владимировна | B4: 2023-09-01 | C4: =YEAR(B4) -> 2023 | D4: =MONTH(B4) -> 9 | E4: =C4&"-"&D4 -> 2023-9 | K4: Алексеев Андрей Кириллович | L4: 2024-4 | N4: Николаев Артур Никитич | O4: =COUNTIF(K:K,N4) -> 8
A5: Сидоров Артем Викторович | B5: 2023-09-04 | C5: =YEAR(B5) -> 2023 | D5: =MONTH(B5) -> 9 | E5: =C5&"-"&D5 -> 2023-9 | K5: Алексеев Дмитрий Станиславович | L5: 2024-8 | N5: Новикова Дарья Викторовна | O5: =COUNTIF(K:K,N5) -> 8
A6: Новиков Алексей Александрович | B6: 2023-09-04 | C6: =YEAR(B6) -> 2023 | D6: =MONTH(B6) -> 9 | E6: =C6&"-"&D6 -> 2023-9 | K6: Алексеев Матвей Кириллович | L6: 2023-9 | N6: Орлов Максим Егорович | O6: =COUNTIF(K:K,N6) -> 8
A7: Сидорова Полина Александровна | B7: 2023-09-04 | C7: =YEAR(B7) -> 2023 | D7: =MONTH(B7) -> 9 | E7: =C7&"-"&D7 -> 2023-9 | K7: Алексеев Матвей Кириллович | L7: 2024-6 | N7: Степанова Анна Никитична | O7: =COUNTIF(K:K,N7) -> 8
A8: Егорова Полина Сергеевна | B8: 2023-09-04 | C8: =YEAR(B8) -> 2023 | D8: =MONTH(B8) -> 9 | E8: =C8&"-"&D8 -> 2023-9 | K8: Алексеев Павел Дмитриевич | L8: 2023-11 | N8: Федорова Вероника Ивановна | O8: =COUNTIF(K:K,N8) -> 8
A9: Смирнов Дмитрий Александрович | B9: 2023-09-05 | C9: =YEAR(B9) -> 2023 | D9: =MONTH(B9) -> 9 | E9: =C9&"-"&D9 -> 2023-9 | K9: Алексеев Павел Дмитриевич | L9: 2024-5 | N9: Алексеева Алиса Ильинична | O9: =COUNTIF(K:K,N9) -> 7
A10: Волкова Татьяна Егоровна | B10: 2023-09-05 | C10: =YEAR(B10) -> 2023 | D10: =MONTH(B10) -> 9 | E10: =C10&"-"&D10 -> 2023-9 | K10: Алексеева Алиса Александровна | L10: 2023-9 | N10: Алексеева Виктория Александровна | O10: =COUNTIF(K:K,N10) -> 7
A11: Петрова Дарья Егоровна | B11: 2023-09-05 | C11: =YEAR(B11) -> 2023 | D11: =MONTH(B11) -> 9 | E11: =C11&"-"&D11 -> 2023-9 | K11: Алексеева Алиса Александровна | L11: 2023-10 | N11: Васильева Наталья Никитична | O11: =COUNTIF(K:K,N11) -> 7
A12: Смирнова София Ивановна | B12: 2023-09-06 | C12: =YEAR(B12) -> 2023 | D12: =MONTH(B12) -> 9 | E12: =C12&"-"&D12 -> 2023-9 | K12: Алексеева Алиса Александровна | L12: 2023-12 | N12: Волкова Наталья Александровна | O12: =COUNTIF(K:K,N12) -> 7
A13: Смирнов Михаил Алексеевич | B13: 2023-09-06 | C13: =YEAR(B13) -> 2023 | D13: =MONTH(B13) -> 9 | E13: =C13&"-"&D13 -> 2023-9 | K13: Алексеева Алиса Александровна | L13: 2024-8 | N13: Иванова Екатерина Егоровна | O13: =COUNTIF(K:K,N13) -> 7
... A196: Павлов Матвей Дмитриевич | B196: 2023-11-16 | C196: =YEAR(B196) -> 2023 | D196: =MONTH(B196) -> 11 | E196: =C196&"-"&D196 -> 2023-11 | K196: Козлов Артем Владимирович | L196: 2024-6 | N196: Смирнова Мария Сергеевна | O196: =COUNTIF(K:K,N196) -> 1
A197: Сидоров Михаил Артемович | B197: 2023-11-16 | C197: =YEAR(B197) -> 2023 | D197: =MONTH(B197) -> 11 | E197: =C197&"-"&D197 -> 2023-11 | K197: Козлов Артур Андреевич | L197: 2023-9
A198: Иванова Ксения Романовна | B198: 2023-11-16 | C198: =YEAR(B198) -> 2023 | D198: =MONTH(B198) -> 11 | E198: =C198&"-"&D198 -> 2023-11 | K198: Козлов Артур Андреевич | L198: 2023-11
A199: Егоров Никита Геннадьевич | B199: 2023-11-17 | C199: =YEAR(B199) -> 2023 | D199: =MONTH(B199) -> 11 | E199: =C199&"-"&D199 -> 2023-11 | K199: Козлов Артур Андреевич | L199: 2023-12
A200: Морозов Андрей Александрович | B200: 2023-11-17 | C200: =YEAR(B200) -> 2023 | D200: =MONTH(B200) -> 11 | E200: =C200&"-"&D200 -> 2023-11 | K200: Козлов Артур Андреевич | L200: 2024-1
A201: Кузнецов Георгий Никитич | B201: 2023-11-17 | C201: =YEAR(B201) -> 2023 | D201: =MONTH(B201) -> 11 | E201: =C201&"-"&D201 -> 2023-11 | K201: Козлов Артур Андреевич | L201: 2024-2
A202: Степанов Дмитрий Владимирович | B202: 2023-11-20 | C202: =YEAR(B202) -> 2023 | D202: =MONTH(B202) -> 11 | E202: =C202&"-"&D202 -> 2023-11 | K202: Козлов Артур Андреевич | L202: 2024-8
A203: Степанов Роман Павлович | B203: 2023-11-20 | C203: =YEAR(B203) -> 2023 | D203: =MONTH(B203) -> 11 | E203: =C203&"-"&D203 -> 2023-11 | K203: Козлов Дмитрий Викторович | L203: 2023-9
A204: Васильева Татьяна Геннадьевна | B204: 2023-11-20 | C204: =YEAR(B204) -> 2023 | D204: =MONTH(B204) -> 11 | E204: =C204&"-"&D204 -> 2023-11 | K204: Козлов Дмитрий Викторович | L204: 2024-5
A205: Волкова Наталья Александровна | B205: 2023-11-20 | C205: =YEAR(B205) -> 2023 | D205: =MONTH(B205) -> 11 | E205: =C205&"-"&D205 -> 2023-11 | K205: Козлов Михаил Артемович | L205: 2024-1
A206: Новикова Дарья Викторовна | B206: 2023-11-20 | C206: =YEAR(B206) -> 2023 | D206: =MONTH(B206) -> 11 | E206: =C206&"-"&D206 -> 2023-11 | K206: Козлов Сергей Ильич | L206: 2024-4
A207: Павлова Анна Михайловна | B207: 2023-11-20 | C207: =YEAR(B207) -> 2023 | D207: =MONTH(B207) -> 11 | E207: =C207&"-"&D207 -> 2023-11 | K207: Козлов Сергей Ильич | L207: 2024-5
A208: Федорова Вероника Ивановна | B208: 2023-11-20 | C208: =YEAR(B208) -> 2023 | D208: =MONTH(B208) -> 11 | E208: =C208&"-"&D208 -> 2023-11 | K208: Козлова Алиса Алексеевна | L208: 2023-10
... A810: Кузнецов Никита Сергеевич | B810: 2024-06-27 | C810: =YEAR(B810) -> 2024 | D810: =MONTH(B810) -> 6 | E810: =C810&"-"&D810 -> 2024-6 | K810: Федорова Татьяна Никитична | L810: 2024-8
A811: Смирнов Кирилл Сергеевич | B811: 2024-06-27 | C811: =YEAR(B811) -> 2024 | D811: =MONTH(B811) -> 6 | E811: =C811&"-"&D811 -> 2024-6
A812: Федорова Вероника Ивановна | B812: 2024-06-28 | C812: =YEAR(B812) -> 2024 | D812: =MONTH(B812) -> 6 | E812: =C812&"-"&D812 -> 2024-6
A813: Алексеев Матвей Кириллович | B813: 2024-06-28 | C813: =YEAR(B813) -> 2024 | D813: =MONTH(B813) -> 6 | E813: =C813&"-"&D813 -> 2024-6
A814: Новиков Иван Никитич | B814: 2024-06-28 | C814: =YEAR(B814) -> 2024 | D814: =MONTH(B814) -> 6 | E814: =C814&"-"&D814 -> 2024-6
A815: Алексеева Алиса Ильинична | B815: 2024-07-01 | C815: =YEAR(B815) -> 2024 | D815: =MONTH(B815) -> 7 | E815: =C815&"-"&D815 -> 2024-7
A816: Васильева Алиса Дмитриевна | B816: 2024-07-01 | C816: =YEAR(B816) -> 2024 | D816: =MONTH(B816) -> 7 | E816: =C816&"-"&D816 -> 2024-7
A817: Алексеева Виктория Александровна | B817: 2024-07-01 | C817: =YEAR(B817) -> 2024 | D817: =MONTH(B817) -> 7 | E817: =C817&"-"&D817 -> 2024-7
A818: Новикова Алиса Юрьевна | B818: 2024-07-01 | C818: =YEAR(B818) -> 2024 | D818: =MONTH(B818) -> 7 | E818: =C818&"-"&D818 -> 2024-7
A819: Алексеева Ксения Андреевна | B819: 2024-07-01 | C819: =YEAR(B819) -> 2024 | D819: =MONTH(B819) -> 7 | E819: =C819&"-"&D819 -> 2024-7
A820: Волкова Валерия Олеговна | B820: 2024-07-01 | C820: =YEAR(B820) -> 2024 | D820: =MONTH(B820) -> 7 | E820: =C820&"-"&D820 -> 2024-7
A821: Козлова Ксения Владимировна | B821: 2024-07-01 | C821: =YEAR(B821) -> 2024 | D821: =MONTH(B821) -> 7 | E821: =C821&"-"&D821 -> 2024-7
A822: Новикова Алиса Юрьевна | B822: 2024-07-01 | C822: =YEAR(B822) -> 2024 | D822: =MONTH(B822) -> 7 | E822: =C822&"-"&D822 -> 2024-7
... A1001: Иванова Александра Никитична | B1001: 2024-09-02 | C1001: =YEAR(B1001) -> 2024 | D1001: =MONTH(B1001) -> 9 | E1001: =C1001&"-"&D1001 -> 2024-9

Sheet задача 3.1
B1: 2023-9 | C1: 2023-10 | D1: 2023-11 | E1: 2023-12 | F1: 2024-1 | G1: 2024-2 | H1: 2024-3 | I1: 2024-4 | J1: 2024-5 | K1: 2024-6 | L1: 2024-7 | M1: 2024-8 | N1: 2024-9
A2: Белов Алексей Константинович | B2: =COUNTIFS('задача 3. данные'!$A:$A,'задача 3.1'!$A2,'задача 3. данные'!$H:$H,'задача 3.1'!B$1) -> 8 | C2: =COUNTIFS('задача 3. данные'!$A:$A,'задача 3.1'!$A2,'задача 3. данные'!$H:$H,'задача 3.1'!C$1) -> 5 | D2: =COUNTIFS('задача 3. данные'!$A:$A,'задача 3.1'!$A2,'задача 3. данные'!$H:$H,'задача 3.1'!D$1) -> 9 | E2: =COUNTIFS('задача 3. данные'!$A:$A,'задача 3.1'!$A2,'задача 3. данные'!$H:$H,'задача 3.1'!E$1) -> 3 | F2: =COUNTIFS('задача 3. данные'!$A:$A,'задача 3.1'!$A2,'задача 3. данные'!$H:$H,'задача 3.1'!F$1) -> 9 | G2: =COUNTIFS('задача 3. данные'!$A:$A,'задача 3.1'!$A2,'задача 3. данные'!$H:$H,'задача 3.1'!G$1) -> 4 | H2: =COUNTIFS('задача 3. данные'!$A:$A,'задача 3.1'!$A2,'задача 3. данные'!$H:$H,'задача 3.1'!H$1) -> 9 | I2: =COUNTIFS('задача 3. данные'!$A:$A,'задача 3.1'!$A2,'задача 3. данные'!$H:$H,'задача 3.1'!I$1) -> 5 | ... N2: =COUNTIFS('задача 3. данные'!$A:$A,'задача 3.1'!$A2,'задача 3. данные'!$H:$H,'задача 3.1'!N$1) -> 0
A3: Громова Мария Ильинична | B3: =COUNTIFS('задача 3. данные'!$A:$A,'задача 3.1'!$A3,'задача 3. данные'!$H:$H,'задача 3.1'!B$1) -> 3 | C3: =COUNTIFS('задача 3. данные'!$A:$A,'задача 3.1'!$A3,'задача 3. данные'!$H:$H,'задача 3.1'!C$1) -> 6 | D3: =COUNTIFS('задача 3. данные'!$A:$A,'задача 3.1'!$A3,'задача 3. данные'!$H:$H,'задача 3.1'!D$1) -> 6 | E3: =COUNTIFS('задача 3. данные'!$A:$A,'задача 3.1'!$A3,'задача 3. данные'!$H:$H,'задача 3.1'!E$1) -> 6 | F3: =COUNTIFS('задача 3. данные'!$A:$A,'задача 3.1'!$A3,'задача 3. данные'!$H:$H,'задача 3.1'!F$1) -> 7 | G3: =COUNTIFS('задача 3. данные'!$A:$A,'задача 3.1'!$A3,'задача 3. данные'!$H:$H,'задача 3.1'!G$1) -> 8 | H3: =COUNTIFS('задача 3. данные'!$A:$A,'задача 3.1'!$A3,'задача 3. данные'!$H:$H,'задача 3.1'!H$1) -> 7 | I3: =COUNTIFS('задача 3. данные'!$A:$A,'задача 3.1'!$A3,'задача 3. данные'!$H:$H,'задача 3.1'!I$1) -> 5 | ... N3: =COUNTIFS('задача 3. данные'!$A:$A,'задача 3.1'!$A3,'задача 3. данные'!$H:$H,'задача 3.1'!N$1) -> 0
A4: Иванова Анна Сергеевна | B4: =COUNTIFS('задача 3. данные'!$A:$A,'задача 3.1'!$A4,'задача 3. данные'!$H:$H,'задача 3.1'!B$1) -> 5 | C4: =COUNTIFS('задача 3. данные'!$A:$A,'задача 3.1'!$A4,'задача 3. данные'!$H:$H,'задача 3.1'!C$1) -> 3 | D4: =COUNTIFS('задача 3. данные'!$A:$A,'задача 3.1'!$A4,'задача 3. данные'!$H:$H,'задача 3.1'!D$1) -> 5 | E4: =COUNTIFS('задача 3. данные'!$A:$A,'задача 3.1'!$A4,'задача 3. данные'!$H:$H,'задача 3.1'!E$1) -> 9 | F4: =COUNTIFS('задача 3. данные'!$A:$A,'задача 3.1'!$A4,'задача 3. данные'!$H:$H,'задача 3.1'!F$1) -> 3 | G4: =COUNTIFS('задача 3. данные'!$A:$A,'задача 3.1'!$A4,'задача 3. данные'!$H:$H,'задача 3.1'!G$1) -> 5 | H4: =COUNTIFS('задача 3. данные'!$A:$A,'задача 3.1'!$A4,'задача 3. данные'!$H:$H,'задача 3.1'!H$1) -> 10 | I4: =COUNTIFS('задача 3. данные'!$A:$A,'задача 3.1'!$A4,'задача 3. данные'!$H:$H,'задача 3.1'!I$1) -> 15 | ... N4: =COUNTIFS('задача 3. данные'!$A:$A,'задача 3.1'!$A4,'задача 3. данные'!$H:$H,'задача 3.1'!N$1) -> 2
A5: Кузнецов Дмитрий Львович | B5: =COUNTIFS('задача 3. данные'!$A:$A,'задача 3.1'!$A5,'задача 3. данные'!$H:$H,'задача 3.1'!B$1) -> 7 | C5: =COUNTIFS('задача 3. данные'!$A:$A,'задача 3.1'!$A5,'задача 3. данные'!$H:$H,'задача 3.1'!C$1) -> 5 | D5: =COUNTIFS('задача 3. данные'!$A:$A,'задача 3.1'!$A5,'задача 3. данные'!$H:$H,'задача 3.1'!D$1) -> 13 | E5: =COUNTIFS('задача 3. данные'!$A:$A,'задача 3.1'!$A5,'задача 3. данные'!$H:$H,'задача 3.1'!E$1) -> 12 | F5: =COUNTIFS('задача 3. данные'!$A:$A,'задача 3.1'!$A5,'задача 3. данные'!$H:$H,'задача 3.1'!F$1) -> 9 | G5: =COUNTIFS('задача 3. данные'!$A:$A,'задача 3.1'!$A5,'задача 3. данные'!$H:$H,'задача 3.1'!G$1) -> 4 | H5: =COUNTIFS('задача 3. данные'!$A:$A,'задача 3.1'!$A5,'задача 3. данные'!$H:$H,'задача 3.1'!H$1) -> 6 | I5: =COUNTIFS('задача 3. данные'!$A:$A,'задача 3.1'!$A5,'задача 3. данные'!$H:$H,'задача 3.1'!I$1) -> 6 | ... N5: =COUNTIFS('задача 3. данные'!$A:$A,'задача 3.1'!$A5,'задача 3. данные'!$H:$H,'задача 3.1'!N$1) -> 0
A6: Новикова Ольга Петровна | B6: =COUNTIFS('задача 3. данные'!$A:$A,'задача 3.1'!$A6,'задача 3. данные'!$H:$H,'задача 3.1'!B$1) -> 10 | C6: =COUNTIFS('задача 3. данные'!$A:$A,'задача 3.1'!$A6,'задача 3. данные'!$H:$H,'задача 3.1'!C$1) -> 7 | D6: =COUNTIFS('задача 3. данные'!$A:$A,'задача 3.1'!$A6,'задача 3. данные'!$H:$H,'задача 3.1'!D$1) -> 6 | E6: =COUNTIFS('задача 3. данные'!$A:$A,'задача 3.1'!$A6,'задача 3. данные'!$H:$H,'задача 3.1'!E$1) -> 4 | F6: =COUNTIFS('задача 3. данные'!$A:$A,'задача 3.1'!$A6,'задача 3. данные'!$H:$H,'задача 3.1'!F$1) -> 7 | G6: =COUNTIFS('задача 3. данные'!$A:$A,'задача 3.1'!$A6,'задача 3. данные'!$H:$H,'задача 3.1'!G$1) -> 3 | H6: =COUNTIFS('задача 3. данные'!$A:$A,'задача 3.1'!$A6,'задача 3. данные'!$H:$H,'задача 3.1'!H$1) -> 6 | I6: =COUNTIFS('задача 3. данные'!$A:$A,'задача 3.1'!$A6,'задача 3. данные'!$H:$H,'задача 3.1'!I$1) -> 8 | ... N6: =COUNTIFS('задача 3. данные'!$A:$A,'задача 3.1'!$A6,'задача 3. данные'!$H:$H,'задача 3.1'!N$1) -> 0
A7: Орлов Павел Денисович | B7: =COUNTIFS('задача 3. данные'!$A:$A,'задача 3.1'!$A7,'задача 3. данные'!$H:$H,'задача 3.1'!B$1) -> 7 | C7: =COUNTIFS('задача 3. данные'!$A:$A,'задача 3.1'!$A7,'задача 3. данные'!$H:$H,'задача 3.1'!C$1) -> 5 | D7: =COUNTIFS('задача 3. данные'!$A:$A,'задача 3.1'!$A7,'задача 3. данные'!$H:$H,'задача 3.1'!D$1) -> 6 | E7: =COUNTIFS('задача 3. данные'!$A:$A,'задача 3.1'!$A7,'задача 3. данные'!$H:$H,'задача 3.1'!E$1) -> 10 | F7: =COUNTIFS('задача 3. данные'!$A:$A,'задача 3.1'!$A7,'задача 3. данные'!$H:$H,'задача 3.1'!F$1) -> 12 | G7: =COUNTIFS('задача 3. данные'!$A:$A,'задача 3.1'!$A7,'задача 3. данные'!$H:$H,'задача 3.1'!G$1) -> 11 | H7: =COUNTIFS('задача 3. данные'!$A:$A,'задача 3.1'!$A7,'задача 3. данные'!$H:$H,'задача 3.1'!H$1) -> 9 | I7: =COUNTIFS('задача 3. данные'!$A:$A,'задача 3.1'!$A7,'задача 3. данные'!$H:$H,'задача 3.1'!I$1) -> 4 | ... N7: =COUNTIFS('задача 3. данные'!$A:$A,'задача 3.1'!$A7,'задача 3. данные'!$H:$H,'задача 3.1'!N$1) -> 0
A8: Петров Владимир Кириллович | B8: =COUNTIFS('задача 3. данные'!$A:$A,'задача 3.1'!$A8,'задача 3. данные'!$H:$H,'задача 3.1'!B$1) -> 5 | C8: =COUNTIFS('задача 3. данные'!$A:$A,'задача 3.1'!$A8,'задача 3. данные'!$H:$H,'задача 3.1'!C$1) -> 10 | D8: =COUNTIFS('задача 3. данные'!$A:$A,'задача 3.1'!$A8,'задача 3. данные'!$H:$H,'задача 3.1'!D$1) -> 9 | E8: =COUNTIFS('задача 3. данные'!$A:$A,'задача 3.1'!$A8,'задача 3. данные'!$H:$H,'задача 3.1'!E$1) -> 7 | F8: =COUNTIFS('задача 3. данные'!$A:$A,'задача 3.1'!$A8,'задача 3. данные'!$H:$H,'задача 3.1'!F$1) -> 7 | G8: =COUNTIFS('задача 3. данные'!$A:$A,'задача 3.1'!$A8,'задача 3. данные'!$H:$H,'задача 3.1'!G$1) -> 9 | H8: =COUNTIFS('задача 3. данные'!$A:$A,'задача 3.1'!$A8,'задача 3. данные'!$H:$H,'задача 3.1'!H$1) -> 7 | I8: =COUNTIFS('задача 3. данные'!$A:$A,'задача 3.1'!$A8,'задача 3. данные'!$H:$H,'задача 3.1'!I$1) -> 6 | ... N8: =COUNTIFS('задача 3. данные'!$A:$A,'задача 3.1'!$A8,'задача 3. данные'!$H:$H,'задача 3.1'!N$1) -> 0
A9: Семенова Ирина Валерьевна | B9: =COUNTIFS('задача 3. данные'!$A:$A,'задача 3.1'!$A9,'задача 3. данные'!$H:$H,'задача 3.1'!B$1) -> 2 | C9: =COUNTIFS('задача 3. данные'!$A:$A,'задача 3.1'!$A9,'задача 3. данные'!$H:$H,'задача 3.1'!C$1) -> 13 | D9: =COUNTIFS('задача 3. данные'!$A:$A,'задача 3.1'!$A9,'задача 3. данные'!$H:$H,'задача 3.1'!D$1) -> 11 | E9: =COUNTIFS('задача 3. данные'!$A:$A,'задача 3.1'!$A9,'задача 3. данные'!$H:$H,'задача 3.1'!E$1) -> 5 | F9: =COUNTIFS('задача 3. данные'!$A:$A,'задача 3.1'!$A9,'задача 3. данные'!$H:$H,'задача 3.1'!F$1) -> 11 | G9: =COUNTIFS('задача 3. данные'!$A:$A,'задача 3.1'!$A9,'задача 3. данные'!$H:$H,'задача 3.1'!G$1) -> 5 | H9: =COUNTIFS('задача 3. данные'!$A:$A,'задача 3.1'!$A9,'задача 3. данные'!$H:$H,'задача 3.1'!H$1) -> 9 | I9: =COUNTIFS('задача 3. данные'!$A:$A,'задача 3.1'!$A9,'задача 3. данные'!$H:$H,'задача 3.1'!I$1) -> 13 | ... N9: =COUNTIFS('задача 3. данные'!$A:$A,'задача 3.1'!$A9,'задача 3. данные'!$H:$H,'задача 3.1'!N$1) -> 0
A10: Сидорова Елена Васильевна | B10: =COUNTIFS('задача 3. данные'!$A:$A,'задача 3.1'!$A10,'задача 3. данные'!$H:$H,'задача 3.1'!B$1) -> 8 | C10: =COUNTIFS('задача 3. данные'!$A:$A,'задача 3.1'!$A10,'задача 3. данные'!$H:$H,'задача 3.1'!C$1) -> 6 | D10: =COUNTIFS('задача 3. данные'!$A:$A,'задача 3.1'!$A10,'задача 3. данные'!$H:$H,'задача 3.1'!D$1) -> 3 | E10: =COUNTIFS('задача 3. данные'!$A:$A,'задача 3.1'!$A10,'задача 3. данные'!$H:$H,'задача 3.1'!E$1) -> 4 | F10: =COUNTIFS('задача 3. данные'!$A:$A,'задача 3.1'!$A10,'задача 3. данные'!$H:$H,'задача 3.1'!F$1) -> 5 | G10: =COUNTIFS('задача 3. данные'!$A:$A,'задача 3.1'!$A10,'задача 3. данные'!$H:$H,'задача 3.1'!G$1) -> 7 | H10: =COUNTIFS('задача 3. данные'!$A:$A,'задача 3.1'!$A10,'задача 3. данные'!$H:$H,'задача 3.1'!H$1) -> 5 | I10: =COUNTIFS('задача 3. данные'!$A:$A,'задача 3.1'!$A10,'задача 3. данные'!$H:$H,'задача 3.1'!I$1) -> 9 | ... N10: =COUNTIFS('задача 3. данные'!$A:$A,'задача 3.1'!$A10,'задача 3. данные'!$H:$H,'задача 3.1'!N$1) -> 0
A11: Ткаченко Андрей Олегович | B11: =COUNTIFS('задача 3. данные'!$A:$A,'задача 3.1'!$A11,'задача 3. данные'!$H:$H,'задача 3.1'!B$1) -> 9 | C11: =COUNTIFS('задача 3. данные'!$A:$A,'задача 3.1'!$A11,'задача 3. данные'!$H:$H,'задача 3.1'!C$1) -> 7 | D11: =COUNTIFS('задача 3. данные'!$A:$A,'задача 3.1'!$A11,'задача 3. данные'!$H:$H,'задача 3.1'!D$1) -> 2 | E11: =COUNTIFS('задача 3. данные'!$A:$A,'задача 3.1'!$A11,'задача 3. данные'!$H:$H,'задача 3.1'!E$1) -> 9 | F11: =COUNTIFS('задача 3. данные'!$A:$A,'задача 3.1'!$A11,'задача 3. данные'!$H:$H,'задача 3.1'!F$1) -> 7 | G11: =COUNTIFS('задача 3. данные'!$A:$A,'задача 3.1'!$A11,'задача 3. данные'!$H:$H,'задача 3.1'!G$1) -> 6 | H11: =COUNTIFS('задача 3. данные'!$A:$A,'задача 3.1'!$A11,'задача 3. данные'!$H:$H,'задача 3.1'!H$1) -> 7 | I11: =COUNTIFS('задача 3. данные'!$A:$A,'задача 3.1'!$A11,'задача 3. данные'!$H:$H,'задача 3.1'!I$1) -> 6 | ... N11: =COUNTIFS('задача 3. данные'!$A:$A,'задача 3.1'!$A11,'задача 3. данные'!$H:$H,'задача 3.1'!N$1) -> 1
A12: Фролов Сергей Викторович | B12: =COUNTIFS('задача 3. данные'!$A:$A,'задача 3.1'!$A12,'задача 3. данные'!$H:$H,'задача 3.1'!B$1) -> 11 | C12: =COUNTIFS('задача 3. данные'!$A:$A,'задача 3.1'!$A12,'задача 3. данные'!$H:$H,'задача 3.1'!C$1) -> 7 | D12: =COUNTIFS('задача 3. данные'!$A:$A,'задача 3.1'!$A12,'задача 3. данные'!$H:$H,'задача 3.1'!D$1) -> 2 | E12: =COUNTIFS('задача 3. данные'!$A:$A,'задача 3.1'!$A12,'задача 3. данные'!$H:$H,'задача 3.1'!E$1) -> 7 | F12: =COUNTIFS('задача 3. данные'!$A:$A,'задача 3.1'!$A12,'задача 3. данные'!$H:$H,'задача 3.1'!F$1) -> 10 | G12: =COUNTIFS('задача 3. данные'!$A:$A,'задача 3.1'!$A12,'задача 3. данные'!$H:$H,'задача 3.1'!G$1) -> 7 | H12: =COUNTIFS('задача 3. данные'!$A:$A,'задача 3.1'!$A12,'задача 3. данные'!$H:$H,'задача 3.1'!H$1) -> 8 | I12: =COUNTIFS('задача 3. данные'!$A:$A,'задача 3.1'!$A12,'задача 3. данные'!$H:$H,'задача 3.1'!I$1) -> 5 | ... N12: =COUNTIFS('задача 3. данные'!$A:$A,'задача 3.1'!$A12,'задача 3. данные'!$H:$H,'задача 3.1'!N$1) -> 0
A13: Яковлев Артем Игоревич | B13: =COUNTIFS('задача 3. данные'!$A:$A,'задача 3.1'!$A13,'задача 3. данные'!$H:$H,'задача 3.1'!B$1) -> 5 | C13: =COUNTIFS('задача 3. данные'!$A:$A,'задача 3.1'!$A13,'задача 3. данные'!$H:$H,'задача 3.1'!C$1) -> 7 | D13: =COUNTIFS('задача 3. данные'!$A:$A,'задача 3.1'!$A13,'задача 3. данные'!$H:$H,'задача 3.1'!D$1) -> 4 | E13: =COUNTIFS('задача 3. данные'!$A:$A,'задача 3.1'!$A13,'задача 3. данные'!$H:$H,'задача 3.1'!E$1) -> 5 | F13: =COUNTIFS('задача 3. данные'!$A:$A,'задача 3.1'!$A13,'задача 3. данные'!$H:$H,'задача 3.1'!F$1) -> 7 | G13: =COUNTIFS('задача 3. данные'!$A:$A,'задача 3.1'!$A13,'задача 3. данные'!$H:$H,'задача 3.1'!G$1) -> 12 | H13: =COUNTIFS('задача 3. данные'!$A:$A,'задача 3.1'!$A13,'задача 3. данные'!$H:$H,'задача 3.1'!H$1) -> 8 | I13: =COUNTIFS('задача 3. данные'!$A:$A,'задача 3.1'!$A13,'задача 3. данные'!$H:$H,'задача 3.1'!I$1) -> 1 | ... N13: =COUNTIFS('задача 3. данные'!$A:$A,'задача 3.1'!$A13,'задача 3. данные'!$H:$H,'задача 3.1'!N$1) -> 0

Sheet задача 3. данные
A1: ФИО менеджера | B1: ФИО клиента | C1: Дата сделки | D1: Сумма сделки | E1: NPS | F1: год | G1: месяц | H1: год-месяц
A2: Ткаченко Андрей Олегович | B2: Лебедев Павел Кириллович | C2: 2023-09-01 | D2: 63205 | E2: 8 | F2: =YEAR(C2) -> 2023 | G2: =MONTH(C2) -> 9 | H2: =F2&"-"&G2 -> 2023-9
A3: Белов Алексей Константинович | B3: Попова Ольга Егоровна | C3: 2023-09-01 | D3: 38636 | E3: 8 | F3: =YEAR(C3) -> 2023 | G3: =MONTH(C3) -> 9 | H3: =F3&"-"&G3 -> 2023-9
A4: Новикова Ольга Петровна | B4: Попова Екатерина Владимировна | C4: 2023-09-01 | D4: 67204 | E4: 6 | F4: =YEAR(C4) -> 2023 | G4: =MONTH(C4) -> 9 | H4: =F4&"-"&G4 -> 2023-9
A5: Сидорова Елена Васильевна | B5: Сидоров Артем Викторович | C5: 2023-09-04 | D5: 84220 | E5: 9 | F5: =YEAR(C5) -> 2023 | G5: =MONTH(C5) -> 9 | H5: =F5&"-"&G5 -> 2023-9
A6: Громова Мария Ильинична | B6: Новиков Алексей Александрович | C6: 2023-09-04 | D6: 78490 | E6: 7 | F6: =YEAR(C6) -> 2023 | G6: =MONTH(C6) -> 9 | H6: =F6&"-"&G6 -> 2023-9
A7: Орлов Павел Денисович | B7: Сидорова Полина Александровна | C7: 2023-09-04 | D7: 58851 | E7: 5 | F7: =YEAR(C7) -> 2023 | G7: =MONTH(C7) -> 9 | H7: =F7&"-"&G7 -> 2023-9
A8: Белов Алексей Константинович | B8: Егорова Полина Сергеевна | C8: 2023-09-04 | D8: 52764 | E8: 8 | F8: =YEAR(C8) -> 2023 | G8: =MONTH(C8) -> 9 | H8: =F8&"-"&G8 -> 2023-9
A9: Новикова Ольга Петровна | B9: Смирнов Дмитрий Александрович | C9: 2023-09-05 | D9: 91862 | E9: 8 | F9: =YEAR(C9) -> 2023 | G9: =MONTH(C9) -> 9 | H9: =F9&"-"&G9 -> 2023-9
A10: Новикова Ольга Петровна | B10: Волкова Татьяна Егоровна | C10: 2023-09-05 | D10: 40540 | E10: 7 | F10: =YEAR(C10) -> 2023 | G10: =MONTH(C10) -> 9 | H10: =F10&"-"&G10 -> 2023-9
A11: Кузнецов Дмитрий Львович | B11: Петрова Дарья Егоровна | C11: 2023-09-05 | D11: 67289 | E11: 5 | F11: =YEAR(C11) -> 2023 | G11: =MONTH(C11) -> 9 | H11: =F11&"-"&G11 -> 2023-9
A12: Сидорова Елена Васильевна | B12: Смирнова София Ивановна | C12: 2023-09-06 | D12: 19382 | E12: 2 | F12: =YEAR(C12) -> 2023 | G12: =MONTH(C12) -> 9 | H12: =F12&"-"&G12 -> 2023-9
A13: Фролов Сергей Викторович | B13: Смирнов Михаил Алексеевич | C13: 2023-09-06 | D13: 38637 | E13: 5 | F13: =YEAR(C13) -> 2023 | G13: =MONTH(C13) -> 9 | H13: =F13&"-"&G13 -> 2023-9
... A1001: Ткаченко Андрей Олегович | B1001: Иванова Александра Никитична | C1001: 2024-09-02 | D1001: 72906 | E1001: 7 | F1001: =YEAR(C1001) -> 2024 | G1001: =MONTH(C1001) -> 9 | H1001: =F1001&"-"&G1001 -> 2024-9

Sheet задача 3.2
B1: 2023-9 | C1: 2023-10 | D1: 2023-11 | E1: 2023-12 | F1: 2024-1 | G1: 2024-2 | H1: 2024-3 | I1: 2024-4 | J1: 2024-5 | K1: 2024-6 | L1: 2024-7 | M1: 2024-8 | N1: 2024-9
A2: Белов Алексей Константинович | B2: =IFERROR( (COUNTIFS('задача 3. данные'!$A:$A,'задача 3.2'!$A2,'задача 3. данные'!$H:$H,'задача 3.2'!B$1,'задача 3. данные'!$E:$E,">=9")- COUNTIFS('задача 3. данные'!$A:$A,'задача 3.2'!$A2,'задача 3. данные'!$H:$H,'задача 3.2'!B$1,'задача 3. данные'!$E:$E,"<=6"))/ COUNTIFS('задача 3. данные'!$A:$A,'задача 3.2'!$A2,'задача 3. данные'!$H:$H,'задача 3.2'!B$1,'задача 3. данные'!$E:$E,">=0"),"") -> 0.125 | C2: =IFERROR( (COUNTIFS('задача 3. данные'!$A:$A,'задача 3.2'!$A2,'задача 3. данные'!$H:$H,'задача 3.2'!C$1,'задача 3. данные'!$E:$E,">=9")- COUNTIFS('задача 3. данные'!$A:$A,'задача 3.2'!$A2,'задача 3. данные'!$H:$H,'задача 3.2'!C$1,'задача 3. данные'!$E:$E,"<=6"))/ COUNTIFS('задача 3. данные'!$A:$A,'задача 3.2'!$A2,'задача 3. данные'!$H:$H,'задача 3.2'!C$1,'задача 3. данные'!$E:$E,">=0"),"") -> -0.4 | D2: =IFERROR( (COUNTIFS('задача 3. данные'!$A:$A,'задача 3.2'!$A2,'задача 3. данные'!$H:$H,'задача 3.2'!D$1,'задача 3. данные'!$E:$E,">=9")- COUNTIFS('задача 3. данные'!$A:$A,'задача 3.2'!$A2,'задача 3. данные'!$H:$H,'задача 3.2'!D$1,'задача 3. данные'!$E:$E,"<=6"))/ COUNTIFS('задача 3. данные'!$A:$A,'задача 3.2'!$A2,'задача 3. данные'!$H:$H,'задача 3.2'!D$1,'задача 3. данные'!$E:$E,">=0"),"") -> -0.44444444 | E2: =IFERROR( (COUNTIFS('задача 3. данные'!$A:$A,'задача 3.2'!$A2,'задача 3. данные'!$H:$H,'задача 3.2'!E$1,'задача 3. данные'!$E:$E,">=9")- COUNTIFS('задача 3. данные'!$A:$A,'задача 3.2'!$A2,'задача 3. данные'!$H:$H,'задача 3.2'!E$1,'задача 3. данные'!$E:$E,"<=6"))/ COUNTIFS('задача 3. данные'!$A:$A,'задача 3.2'!$A2,'задача 3. данные'!$H:$H,'задача 3.2'!E$1,'задача 3. данные'!$E:$E,">=0"),"") -> -1 | F2: =IFERROR( (COUNTIFS('задача 3. данные'!$A:$A,'задача 3.2'!$A2,'задача 3. данные'!$H:$H,'задача 3.2'!F$1,'задача 3. данные'!$E:$E,">=9")- COUNTIFS('задача 3. данные'!$A:$A,'задача 3.2'!$A2,'задача 3. данные'!$H:$H,'задача 3.2'!F$1,'задача 3. данные'!$E:$E,"<=6"))/ COUNTIFS('задача 3. данные'!$A:$A,'задача 3.2'!$A2,'задача 3. данные'!$H:$H,'задача 3.2'!F$1,'задача 3. данные'!$E:$E,">=0"),"") -> -0.33333333 | G2: =IFERROR( (COUNTIFS('задача 3. данные'!$A:$A,'задача 3.2'!$A2,'задача 3. данные'!$H:$H,'задача 3.2'!G$1,'задача 3. данные'!$E:$E,">=9")- COUNTIFS('задача 3. данные'!$A:$A,'задача 3.2'!$A2,'задача 3. данные'!$H:$H,'задача 3.2'!G$1,'задача 3. данные'!$E:$E,"<=6"))/ COUNTIFS('задача 3. данные'!$A:$A,'задача 3.2'!$A2,'задача 3. данные'!$H:$H,'задача 3.2'!G$1,'задача 3. данные'!$E:$E,">=0"),"") -> -0.5 | H2: =IFERROR( (COUNTIFS('задача 3. данные'!$A:$A,'задача 3.2'!$A2,'задача 3. данные'!$H:$H,'задача 3.2'!H$1,'задача 3. данные'!$E:$E,">=9")- COUNTIFS('задача 3. данные'!$A:$A,'задача 3.2'!$A2,'задача 3. данные'!$H:$H,'задача 3.2'!H$1,'задача 3. данные'!$E:$E,"<=6"))/ COUNTIFS('задача 3. данные'!$A:$A,'задача 3.2'!$A2,'задача 3. данные'!$H:$H,'задача 3.2'!H$1,'задача 3. данные'!$E:$E,">=0"),"") -> -0.11111111 | I2: =IFERROR( (COUNTIFS('задача 3. данные'!$A:$A,'задача 3.2'!$A2,'задача 3. данные'!$H:$H,'задача 3.2'!I$1,'задача 3. данные'!$E:$E,">=9")- COUNTIFS('задача 3. данные'!$A:$A,'задача 3.2'!$A2,'задача 3. данные'!$H:$H,'задача 3.2'!I$1,'задача 3. данные'!$E:$E,"<=6"))/ COUNTIFS('задача 3. данные'!$A:$A,'задача 3.2'!$A2,'задача 3. данные'!$H:$H,'задача 3.2'!I$1,'задача 3. данные'!$E:$E,">=0"),"") -> -0.6 | ... N2: =IFERROR( (COUNTIFS('задача 3. данные'!$A:$A,'задача 3.2'!$A2,'задача 3. данные'!$H:$H,'задача 3.2'!N$1,'задача 3. данные'!$E:$E,">=9")- COUNTIFS('задача 3. данные'!$A:$A,'задача 3.2'!$A2,'задача 3. данные'!$H:$H,'задача 3.2'!N$1,'задача 3. данные'!$E:$E,"<=6"))/ COUNTIFS('задача 3. данные'!$A:$A,'задача 3.2'!$A2,'задача 3. данные'!$H:$H,'задача 3.2'!N$1,'задача 3. данные'!$E:$E,">=0"),"")
A3: Громова Мария Ильинична | B3: =IFERROR( (COUNTIFS('задача 3. данные'!$A:$A,'задача 3.2'!$A3,'задача 3. данные'!$H:$H,'задача 3.2'!B$1,'задача 3. данные'!$E:$E,">=9")- COUNTIFS('задача 3. данные'!$A:$A,'задача 3.2'!$A3,'задача 3. данные'!$H:$H,'задача 3.2'!B$1,'задача 3. данные'!$E:$E,"<=6"))/ COUNTIFS('задача 3. данные'!$A:$A,'задача 3.2'!$A3,'задача 3. данные'!$H:$H,'задача 3.2'!B$1,'задача 3. данные'!$E:$E,">=0"),"") -> -0.33333333 | C3: =IFERROR( (COUNTIFS('задача 3. данные'!$A:$A,'задача 3.2'!$A3,'задача 3. данные'!$H:$H,'задача 3.2'!C$1,'задача 3. данные'!$E:$E,">=9")- COUNTIFS('задача 3. данные'!$A:$A,'задача 3.2'!$A3,'задача 3. данные'!$H:$H,'задача 3.2'!C$1,'задача 3. данные'!$E:$E,"<=6"))/ COUNTIFS('задача 3. данные'!$A:$A,'задача 3.2'!$A3,'задача 3. данные'!$H:$H,'задача 3.2'!C$1,'задача 3. данные'!$E:$E,">=0"),"") -> -0.16666667 | D3: =IFERROR( (COUNTIFS('задача 3. данные'!$A:$A,'задача 3.2'!$A3,'задача 3. данные'!$H:$H,'задача 3.2'!D$1,'задача 3. данные'!$E:$E,">=9")- COUNTIFS('задача 3. данные'!$A:$A,'задача 3.2'!$A3,'задача 3. данные'!$H:$H,'задача 3.2'!D$1,'задача 3. данные'!$E:$E,"<=6"))/ COUNTIFS('задача 3. данные'!$A:$A,'задача 3.2'!$A3,'задача 3. данные'!$H:$H,'задача 3.2'!D$1,'задача 3. данные'!$E:$E,">=0"),"") -> -0.16666667 | E3: =IFERROR( (COUNTIFS('задача 3. данные'!$A:$A,'задача 3.2'!$A3,'задача 3. данные'!$H:$H,'задача 3.2'!E$1,'задача 3. данные'!$E:$E,">=9")- COUNTIFS('задача 3. данные'!$A:$A,'задача 3.2'!$A3,'задача 3. данные'!$H:$H,'задача 3.2'!E$1,'задача 3. данные'!$E:$E,"<=6"))/ COUNTIFS('задача 3. данные'!$A:$A,'задача 3.2'!$A3,'задача 3. данные'!$H:$H,'задача 3.2'!E$1,'задача 3. данные'!$E:$E,">=0"),"") -> -0.16666667 | F3: =IFERROR( (COUNTIFS('задача 3. данные'!$A:$A,'задача 3.2'!$A3,'задача 3. данные'!$H:$H,'задача 3.2'!F$1,'задача 3. данные'!$E:$E,">=9")- COUNTIFS('задача 3. данные'!$A:$A,'задача 3.2'!$A3,'задача 3. данные'!$H:$H,'задача 3.2'!F$1,'задача 3. данные'!$E:$E,"<=6"))/ COUNTIFS('задача 3. данные'!$A:$A,'задача 3.2'!$A3,'задача 3. данные'!$H:$H,'задача 3.2'!F$1,'задача 3. данные'!$E:$E,">=0"),"") -> -0.14285714 | G3: =IFERROR( (COUNTIFS('задача 3. данные'!$A:$A,'задача 3.2'!$A3,'задача 3. данные'!$H:$H,'задача 3.2'!G$1,'задача 3. данные'!$E:$E,">=9")- COUNTIFS('задача 3. данные'!$A:$A,'задача 3.2'!$A3,'задача 3. данные'!$H:$H,'задача 3.2'!G$1,'задача 3. данные'!$E:$E,"<=6"))/ COUNTIFS('задача 3. данные'!$A:$A,'задача 3.2'!$A3,'задача 3. данные'!$H:$H,'задача 3.2'!G$1,'задача 3. данные'!$E:$E,">=0"),"") -> -0.25 | H3: =IFERROR( (COUNTIFS('задача 3. данные'!$A:$A,'задача 3.2'!$A3,'задача 3. данные'!$H:$H,'задача 3.2'!H$1,'задача 3. данные'!$E:$E,">=9")- COUNTIFS('задача 3. данные'!$A:$A,'задача 3.2'!$A3,'задача 3. данные'!$H:$H,'задача 3.2'!H$1,'задача 3. данные'!$E:$E,"<=6"))/ COUNTIFS('задача 3. данные'!$A:$A,'задача 3.2'!$A3,'задача 3. данные'!$H:$H,'задача 3.2'!H$1,'задача 3. данные'!$E:$E,">=0"),"") -> -0.57142857 | I3: =IFERROR( (COUNTIFS('задача 3. данные'!$A:$A,'задача 3.2'!$A3,'задача 3. данные'!$H:$H,'задача 3.2'!I$1,'задача 3. данные'!$E:$E,">=9")- COUNTIFS('задача 3. данные'!$A:$A,'задача 3.2'!$A3,'задача 3. данные'!$H:$H,'задача 3.2'!I$1,'задача 3. данные'!$E:$E,"<=6"))/ COUNTIFS('задача 3. данные'!$A:$A,'задача 3.2'!$A3,'задача 3. данные'!$H:$H,'задача 3.2'!I$1,'задача 3. данные'!$E:$E,">=0"),"") -> -0.2 | ... N3: =IFERROR( (COUNTIFS('задача 3. данные'!$A:$A,'задача 3.2'!$A3,'задача 3. данные'!$H:$H,'задача 3.2'!N$1,'задача 3. данные'!$E:$E,">=9")- COUNTIFS('задача 3. данные'!$A:$A,'задача 3.2'!$A3,'задача 3. данные'!$H:$H,'задача 3.2'!N$1,'задача 3. данные'!$E:$E,"<=6"))/ COUNTIFS('задача 3. данные'!$A:$A,'задача 3.2'!$A3,'задача 3. данные'!$H:$H,'задача 3.2'!N$1,'задача 3. данные'!$E:$E,">=0"),"")
